Workbook

Sheet Scores
A1: Port Campbell Pennant 2026 - F Class Scratch Scores
A2: Name | B2: Class | C2: Club | D2: PCRC 2025 | E2: GRC 2025 | F2: BMRC 2025 | G2: CRC 2026 | H2: Average MCSI Score | I2: Target MCSI Benchmark | J2: R1 Comp Scratch | K2: R1 Comp Centres | L2: R1 Lookup | M2: R1 MCSI | N2: R2 Comp Scratch | O2: R2 Comp Centres | P2: R2 Lookup | Q2: R2 MCSI | R2: Total MCSI (R1 + R2) | S2: Handicap (2x Range) | T2: Handicap Adjusted Score | U2: Rank | V2: Scratch Agg | W2: Scratch Agg Centres
A3: Bela Ori | B3: FS | C3: BMRC | E3: 161.5 | F3: 141.5 | H3: =IF(COUNT(D3:G3)=0,"",ROUND(AVERAGE(D3:G3),1)) -> 151.5 | I3: =IFERROR(VLOOKUP(B3,Settings!$A$8:$B$11,2,FALSE),"") -> 190 | J3: 59 | K3: 4 | L3: =IF(OR(J3="",K3=""),"",J3+K3) -> 63 | M3: =IFERROR(INDEX(MCSI_Table!$B$2:$E$72,MATCH(L3,MCSI_Table!$A$2:$A$72,0),MATCH(B3,MCSI_Table!$B$1:$E$1,0)),"") -> 90 | N3: 60 | O3: 6 | P3: =IF(OR(N3="",O3=""),"",N3+O3) -> 66 | Q3: =IFERROR(INDEX(MCSI_Table!$B$2:$E$72,MATCH(P3,MCSI_Table!$A$2:$A$72,0),MATCH(B3,MCSI_Table!$B$1:$E$1,0)),"") -> 94.3 | R3: =IF(OR(M3="",Q3=""),"",ROUND(M3+Q3,1)) -> 184.3 | S3: =IF(OR(B3="",H3="",COUNT(D3:F3)<Settings!$B$5),"",ROUND((I3-H3)*Settings!$B$3,1)) -> 27 | T3: =IF(OR(R3="",S3=""),"",ROUND(R3+S3,1)) -> 211.3 | U3: =IF(ISNUMBER(T3),1+COUNTIF($T$3:$T$51,">"&T3),"") -> 1 | V3: =ScoresTable[[#This Row],[R1 Comp Scratch]]+ScoresTable[[#This Row],[R2 Comp Scratch]] -> 119 | W3: =ScoresTable[[#This Row],[R1 Comp Centres]]+ScoresTable[[#This Row],[R2 Comp Centres]] -> 10
A4: Maya Ori | B4: FS | C4: BMRC | E4: 167.2 | F4: 150 | H4: =IF(COUNT(D4:G4)=0,"",ROUND(AVERAGE(D4:G4),1)) -> 158.6 | I4: =IFERROR(VLOOKUP(B4,Settings!$A$8:$B$11,2,FALSE),"") -> 190 | J4: 58 | K4: 3 | L4: =IF(OR(J4="",K4=""),"",J4+K4) -> 61 | M4: =IFERROR(INDEX(MCSI_Table!$B$2:$E$72,MATCH(L4,MCSI_Table!$A$2:$A$72,0),MATCH(B4,MCSI_Table!$B$1:$E$1,0)),"") -> 87.1 | N4: 59 | O4: 6 | P4: =IF(OR(N4="",O4=""),"",N4+O4) -> 65 | Q4: =IFERROR(INDEX(MCSI_Table!$B$2:$E$72,MATCH(P4,MCSI_Table!$A$2:$A$72,0),MATCH(B4,MCSI_Table!$B$1:$E$1,0)),"") -> 92.9 | R4: =IF(OR(M4="",Q4=""),"",ROUND(M4+Q4,1)) -> 180 | S4: =IF(OR(B4="",H4="",COUNT(D4:F4)<Settings!$B$5),"",ROUND((I4-H4)*Settings!$B$3,1)) -> 22 | T4: =IF(OR(R4="",S4=""),"",ROUND(R4+S4,1)) -> 202 | U4: =IF(ISNUMBER(T4),1+COUNTIF($T$3:$T$51,">"&T4),"") -> 2 | V4: =ScoresTable[[#This Row],[R1 Comp Scratch]]+ScoresTable[[#This Row],[R2 Comp Scratch]] -> 117 | W4: =ScoresTable[[#This Row],[R1 Comp Centres]]+ScoresTable[[#This Row],[R2 Comp Centres]] -> 9
A5: Brendan Wilson | B5: FO | C5: CRC | E5: 180 | F5: 138.6 | G5: 165.8 | H5: =IF(COUNT(D5:G5)=0,"",ROUND(AVERAGE(D5:G5),1)) -> 161.5 | I5: =IFERROR(VLOOKUP(B5,Settings!$A$8:$B$11,2,FALSE),"") -> 190 | J5: 60 | K5: 7 | L5: =IF(OR(J5="",K5=""),"",J5+K5) -> 67 | M5: =IFERROR(INDEX(MCSI_Table!$B$2:$E$72,MATCH(L5,MCSI_Table!$A$2:$A$72,0),MATCH(B5,MCSI_Table!$B$1:$E$1,0)),"") -> 92.4 | N5: 60 | O5: 5 | P5: =IF(OR(N5="",O5=""),"",N5+O5) -> 65 | Q5: =IFERROR(INDEX(MCSI_Table!$B$2:$E$72,MATCH(P5,MCSI_Table!$A$2:$A$72,0),MATCH(B5,MCSI_Table!$B$1:$E$1,0)),"") -> 88.9 | R5: =IF(OR(M5="",Q5=""),"",ROUND(M5+Q5,1)) -> 181.3 | S5: =IF(OR(B5="",H5="",COUNT(D5:F5)<Settings!$B$5),"",ROUND((I5-H5)*Settings!$B$3,1)) -> 20 | T5: =IF(OR(R5="",S5=""),"",ROUND(R5+S5,1)) -> 201.3 | U5: =IF(ISNUMBER(T5),1+COUNTIF($T$3:$T$51,">"&T5),"") -> 3 | V5: =ScoresTable[[#This Row],[R1 Comp Scratch]]+ScoresTable[[#This Row],[R2 Comp Scratch]] -> 120 | W5: =ScoresTable[[#This Row],[R1 Comp Centres]]+ScoresTable[[#This Row],[R2 Comp Centres]] -> 12
A6: Andrew Cook | B6: FS | C6: GRC | E6: 172.8 | F6: 147.1 | G6: 180 | H6: =IF(COUNT(D6:G6)=0,"",ROUND(AVERAGE(D6:G6),1)) -> 166.6 | I6: =IFERROR(VLOOKUP(B6,Settings!$A$8:$B$11,2,FALSE),"") -> 190 | J6: 60 | K6: 4 | L6: =IF(OR(J6="",K6=""),"",J6+K6) -> 64 | M6: =IFERROR(INDEX(MCSI_Table!$B$2:$E$72,MATCH(L6,MCSI_Table!$A$2:$A$72,0),MATCH(B6,MCSI_Table!$B$1:$E$1,0)),"") -> 91.4 | N6: 57 | O6: 6 | P6: =IF(OR(N6="",O6=""),"",N6+O6) -> 63 | Q6: =IFERROR(INDEX(MCSI_Table!$B$2:$E$72,MATCH(P6,MCSI_Table!$A$2:$A$72,0),MATCH(B6,MCSI_Table!$B$1:$E$1,0)),"") -> 90 | R6: =IF(OR(M6="",Q6=""),"",ROUND(M6+Q6,1)) -> 181.4 | S6: =IF(OR(B6="",H6="",COUNT(D6:F6)<Settings!$B$5),"",ROUND((I6-H6)*Settings!$B$3,1)) -> 16.4 | T6: =IF(OR(R6="",S6=""),"",ROUND(R6+S6,1)) -> 197.8 | U6: =IF(ISNUMBER(T6),1+COUNTIF($T$3:$T$51,">"&T6),"") -> 4 | V6: =ScoresTable[[#This Row],[R1 Comp Scratch]]+ScoresTable[[#This Row],[R2 Comp Scratch]] -> 117 | W6: =ScoresTable[[#This Row],[R1 Comp Centres]]+ScoresTable[[#This Row],[R2 Comp Centres]] -> 10
A7: David Shepard | B7: FS | C7: GRC | E7: 164.3 | F7: 144.3 | G7: 167.1 | H7: =IF(COUNT(D7:G7)=0,"",ROUND(AVERAGE(D7:G7),1)) -> 158.6 | I7: =IFERROR(VLOOKUP(B7,Settings!$A$8:$B$11,2,FALSE),"") -> 190 | J7: 57 | K7: 2 | L7: =IF(OR(J7="",K7=""),"",J7+K7) -> 59 | M7: =IFERROR(INDEX(MCSI_Table!$B$2:$E$72,MATCH(L7,MCSI_Table!$A$2:$A$72,0),MATCH(B7,MCSI_Table!$B$1:$E$1,0)),"") -> 84.3 | N7: 59 | O7: 4 | P7: =IF(OR(N7="",O7=""),"",N7+O7) -> 63 | Q7: =IFERROR(INDEX(MCSI_Table!$B$2:$E$72,MATCH(P7,MCSI_Table!$A$2:$A$72,0),MATCH(B7,MCSI_Table!$B$1:$E$1,0)),"") -> 90 | R7: =IF(OR(M7="",Q7=""),"",ROUND(M7+Q7,1)) -> 174.3 | S7: =IF(OR(B7="",H7="",COUNT(D7:F7)<Settings!$B$5),"",ROUND((I7-H7)*Settings!$B$3,1)) -> 22 | T7: =IF(OR(R7="",S7=""),"",ROUND(R7+S7,1)) -> 196.3 | U7: =IF(ISNUMBER(T7),1+COUNTIF($T$3:$T$51,">"&T7),"") -> 5 | V7: =ScoresTable[[#This Row],[R1 Comp Scratch]]+ScoresTable[[#This Row],[R2 Comp Scratch]] -> 116 | W7: =ScoresTable[[#This Row],[R1 Comp Centres]]+ScoresTable[[#This Row],[R2 Comp Centres]] -> 6
A8: Mike Evans | B8: FS | C8: CRC | E8: 185.7 | F8: 162.9 | G8: 161.5 | H8: =IF(COUNT(D8:G8)=0,"",ROUND(AVERAGE(D8:G8),1)) -> 170 | I8: =IFERROR(VLOOKUP(B8,Settings!$A$8:$B$11,2,FALSE),"") -> 190 | J8: 60 | K8: 6 | L8: =IF(OR(J8="",K8=""),"",J8+K8) -> 66 | M8: =IFERROR(INDEX(MCSI_Table!$B$2:$E$72,MATCH(L8,MCSI_Table!$A$2:$A$72,0),MATCH(B8,MCSI_Table!$B$1:$E$1,0)),"") -> 94.3 | N8: 58 | O8: 3 | P8: =IF(OR(N8="",O8=""),"",N8+O8) -> 61 | Q8: =IFERROR(INDEX(MCSI_Table!$B$2:$E$72,MATCH(P8,MCSI_Table!$A$2:$A$72,0),MATCH(B8,MCSI_Table!$B$1:$E$1,0)),"") -> 87.1 | R8: =IF(OR(M8="",Q8=""),"",ROUND(M8+Q8,1)) -> 181.4 | S8: =IF(OR(B8="",H8="",COUNT(D8:F8)<Settings!$B$5),"",ROUND((I8-H8)*Settings!$B$3,1)) -> 14 | T8: =IF(OR(R8="",S8=""),"",ROUND(R8+S8,1)) -> 195.4 | U8: =IF(ISNUMBER(T8),1+COUNTIF($T$3:$T$51,">"&T8),"") -> 6 | V8: =ScoresTable[[#This Row],[R1 Comp Scratch]]+ScoresTable[[#This Row],[R2 Comp Scratch]] -> 118 | W8: =ScoresTable[[#This Row],[R1 Comp Centres]]+ScoresTable[[#This Row],[R2 Comp Centres]] -> 9
A9: Shane Malcolm | B9: FS | C9: BMRC | F9: 152.8 | H9: =IF(COUNT(D9:G9)=0,"",ROUND(AVERAGE(D9:G9),1)) -> 152.8 | I9: =IFERROR(VLOOKUP(B9,Settings!$A$8:$B$11,2,FALSE),"") -> 190 | J9: 58 | K9: 3 | L9: =IF(OR(J9="",K9=""),"",J9+K9) -> 61 | M9: =IFERROR(INDEX(MCSI_Table!$B$2:$E$72,MATCH(L9,MCSI_Table!$A$2:$A$72,0),MATCH(B9,MCSI_Table!$B$1:$E$1,0)),"") -> 87.1 | N9: 55 | O9: 2 | P9: =IF(OR(N9="",O9=""),"",N9+O9) -> 57 | Q9: =IFERROR(INDEX(MCSI_Table!$B$2:$E$72,MATCH(P9,MCSI_Table!$A$2:$A$72,0),MATCH(B9,MCSI_Table!$B$1:$E$1,0)),"") -> 81.4 | R9: =IF(OR(M9="",Q9=""),"",ROUND(M9+Q9,1)) -> 168.5 | S9: =IF(OR(B9="",H9="",COUNT(D9:F9)<Settings!$B$5),"",ROUND((I9-H9)*Settings!$B$3,1)) -> 26 | T9: =IF(OR(R9="",S9=""),"",ROUND(R9+S9,1)) -> 194.5 | U9: =IF(ISNUMBER(T9),1+COUNTIF($T$3:$T$51,">"&T9),"") -> 7 | V9: =ScoresTable[[#This Row],[R1 Comp Scratch]]+ScoresTable[[#This Row],[R2 Comp Scratch]] -> 113 | W9: =ScoresTable[[#This Row],[R1 Comp Centres]]+ScoresTable[[#This Row],[R2 Comp Centres]] -> 5
A10: Neil Mann | B10: FO | C10: GRC | E10: 167.7 | F10: 127.9 | G10: 167.8 | H10: =IF(COUNT(D10:G10)=0,"",ROUND(AVERAGE(D10:G10),1)) -> 154.5 | I10: =IFERROR(VLOOKUP(B10,Settings!$A$8:$B$11,2,FALSE),"") -> 190 | J10: 59 | K10: 3 | L10: =IF(OR(J10="",K10=""),"",J10+K10) -> 62 | M10: =IFERROR(INDEX(MCSI_Table!$B$2:$E$72,MATCH(L10,MCSI_Table!$A$2:$A$72,0),MATCH(B10,MCSI_Table!$B$1:$E$1,0)),"") -> 83.8 | N10: 57 | O10: 3 | P10: =IF(OR(N10="",O10=""),"",N10+O10) -> 60 | Q10: =IFERROR(INDEX(MCSI_Table!$B$2:$E$72,MATCH(P10,MCSI_Table!$A$2:$A$72,0),MATCH(B10,MCSI_Table!$B$1:$E$1,0)),"") -> 80.5 | R10: =IF(OR(M10="",Q10=""),"",ROUND(M10+Q10,1)) -> 164.3 | S10: =IF(OR(B10="",H10="",COUNT(D10:F10)<Settings!$B$5),"",ROUND((I10-H10)*Settings!$B$3,1)) -> 24.9 | T10: =IF(OR(R10="",S10=""),"",ROUND(R10+S10,1)) -> 189.2 | U10: =IF(ISNUMBER(T10),1+COUNTIF($T$3:$T$51,">"&T10),"") -> 8 | V10: =ScoresTable[[#This Row],[R1 Comp Scratch]]+ScoresTable[[#This Row],[R2 Comp Scratch]] -> 116 | W10: =ScoresTable[[#This Row],[R1 Comp Centres]]+ScoresTable[[#This Row],[R2 Comp Centres]] -> 6
A11: Lisa Donnelly | B11: FS | C11: GRC | E11: 170 | F11: 157.1 | H11: =IF(COUNT(D11:G11)=0,"",ROUND(AVERAGE(D11:G11),1)) -> 163.6 | I11: =IFERROR(VLOOKUP(B11,Settings!$A$8:$B$11,2,FALSE),"") -> 190 | J11: 58 | K11: 2 | L11: =IF(OR(J11="",K11=""),"",J11+K11) -> 60 | M11: =IFERROR(INDEX(MCSI_Table!$B$2:$E$72,MATCH(L11,MCSI_Table!$A$2:$A$72,0),MATCH(B11,MCSI_Table!$B$1:$E$1,0)),"") -> 85.7 | N11: 55 | O11: 3 | P11: =IF(OR(N11="",O11=""),"",N11+O11) -> 58 | Q11: =IFERROR(INDEX(MCSI_Table!$B$2:$E$72,MATCH(P11,MCSI_Table!$A$2:$A$72,0),MATCH(B11,MCSI_Table!$B$1:$E$1,0)),"") -> 82.9 | R11: =IF(OR(M11="",Q11=""),"",ROUND(M11+Q11,1)) -> 168.6 | S11: =IF(OR(B11="",H11="",COUNT(D11:F11)<Settings!$B$5),"",ROUND((I11-H11)*Settings!$B$3,1)) -> 18.5 | T11: =IF(OR(R11="",S11=""),"",ROUND(R11+S11,1)) -> 187.1 | U11: =IF(ISNUMBER(T11),1+COUNTIF($T$3:$T$51,">"&T11),"") -> 9 | V11: =ScoresTable[[#This Row],[R1 Comp Scratch]]+ScoresTable[[#This Row],[R2 Comp Scratch]] -> 113 | W11: =ScoresTable[[#This Row],[R1 Comp Centres]]+ScoresTable[[#This Row],[R2 Comp Centres]] -> 5
A12: Garry Rose | B12: FO | C12: CRC | E12: 183 | F12: 149.1 | G12: 172.7 | H12: =IF(COUNT(D12:G12)=0,"",ROUND(AVERAGE(D12:G12),1)) -> 168.3 | I12: =IFERROR(VLOOKUP(B12,Settings!$A$8:$B$11,2,FALSE),"") -> 190 | J12: 59 | K12: 2 | L12: =IF(OR(J12="",K12=""),"",J12+K12) -> 61 | M12: =IFERROR(INDEX(MCSI_Table!$B$2:$E$72,MATCH(L12,MCSI_Table!$A$2:$A$72,0),MATCH(B12,MCSI_Table!$B$1:$E$1,0)),"") -> 82.2 | N12: 60 | O12: 5 | P12: =IF(OR(N12="",O12=""),"",N12+O12) -> 65 | Q12: =IFERROR(INDEX(MCSI_Table!$B$2:$E$72,MATCH(P12,MCSI_Table!$A$2:$A$72,0),MATCH(B12,MCSI_Table!$B$1:$E$1,0)),"") -> 88.9 | R12: =IF(OR(M12="",Q12=""),"",ROUND(M12+Q12,1)) -> 171.1 | S12: =IF(OR(B12="",H12="",COUNT(D12:F12)<Settings!$B$5),"",ROUND((I12-H12)*Settings!$B$3,1)) -> 15.2 | T12: =IF(OR(R12="",S12=""),"",ROUND(R12+S12,1)) -> 186.3 | U12: =IF(ISNUMBER(T12),1+COUNTIF($T$3:$T$51,">"&T12),"") -> 10 | V12: =ScoresTable[[#This Row],[R1 Comp Scratch]]+ScoresTable[[#This Row],[R2 Comp Scratch]] -> 119 | W12: =ScoresTable[[#This Row],[R1 Comp Centres]]+ScoresTable[[#This Row],[R2 Comp Centres]] -> 7
A13: Philip Sternhoght | B13: FS | C13: CRC | E13: 165 | F13: 165 | G13: 165 | H13: =IF(COUNT(D13:G13)=0,"",ROUND(AVERAGE(D13:G13),1)) -> 165 | I13: =IFERROR(VLOOKUP(B13,Settings!$A$8:$B$11,2,FALSE),"") -> 190 | J13: 55 | K13: 1 | L13: =IF(OR(J13="",K13=""),"",J13+K13) -> 56 | M13: =IFERROR(INDEX(MCSI_Table!$B$2:$E$72,MATCH(L13,MCSI_Table!$A$2:$A$72,0),MATCH(B13,MCSI_Table!$B$1:$E$1,0)),"") -> 80 | N13: 57 | O13: 4 | P13: =IF(OR(N13="",O13=""),"",N13+O13) -> 61 | Q13: =IFERROR(INDEX(MCSI_Table!$B$2:$E$72,MATCH(P13,MCSI_Table!$A$2:$A$72,0),MATCH(B13,MCSI_Table!$B$1:$E$1,0)),"") -> 87.1 | R13: =IF(OR(M13="",Q13=""),"",ROUND(M13+Q13,1)) -> 167.1 | S13: =IF(OR(B13="",H13="",COUNT(D13:F13)<Settings!$B$5),"",ROUND((I13-H13)*Settings!$B$3,1)) -> 17.5 | T13: =IF(OR(R13="",S13=""),"",ROUND(R13+S13,1)) -> 184.6 | U13: =IF(ISNUMBER(T13),1+COUNTIF($T$3:$T$51,">"&T13),"") -> 11 | V13: =ScoresTable[[#This Row],[R1 Comp Scratch]]+ScoresTable[[#This Row],[R2 Comp Scratch]] -> 112 | W13: =ScoresTable[[#This Row],[R1 Comp Centres]]+ScoresTable[[#This Row],[R2 Comp Centres]] -> 5
A14: John Halifax | B14: FO | C14: CRC | F14: 176.1 | G14: 182 | H14: =IF(COUNT(D14:G14)=0,"",ROUND(AVERAGE(D14:G14),1)) -> 179.1 | I14: =IFERROR(VLOOKUP(B14,Settings!$A$8:$B$11,2,FALSE),"") -> 190 | J14: 57 | K14: 2 | L14: =IF(OR(J14="",K14=""),"",J14+K14) -> 59 | M14: =IFERROR(INDEX(MCSI_Table!$B$2:$E$72,MATCH(L14,MCSI_Table!$A$2:$A$72,0),MATCH(B14,MCSI_Table!$B$1:$E$1,0)),"") -> 78.8 | N14: 60 | O14: 4 | P14: =IF(OR(N14="",O14=""),"",N14+O14) -> 64 | Q14: =IFERROR(INDEX(MCSI_Table!$B$2:$E$72,MATCH(P14,MCSI_Table!$A$2:$A$72,0),MATCH(B14,MCSI_Table!$B$1:$E$1,0)),"") -> 87.2 | R14: =IF(OR(M14="",Q14=""),"",ROUND(M14+Q14,1)) -> 166 | S14: =IF(OR(B14="",H14="",COUNT(D14:F14)<Settings!$B$5),"",ROUND((I14-H14)*Settings!$B$3,1)) -> 7.6 | T14: =IF(OR(R14="",S14=""),"",ROUND(R14+S14,1)) -> 173.6 | U14: =IF(ISNUMBER(T14),1+COUNTIF($T$3:$T$51,">"&T14),"") -> 12 | V14: =ScoresTable[[#This Row],[R1 Comp Scratch]]+ScoresTable[[#This Row],[R2 Comp Scratch]] -> 117 | W14: =ScoresTable[[#This Row],[R1 Comp Centres]]+ScoresTable[[#This Row],[R2 Comp Centres]] -> 6
A15: Richard Glen | B15: FS | C15: BMRC | E15: 158.6 | F15: 137.1 | H15: =IF(COUNT(D15:G15)=0,"",ROUND(AVERAGE(D15:G15),1)) -> 147.9 | I15: =IFERROR(VLOOKUP(B15,Settings!$A$8:$B$11,2,FALSE),"") -> 190 | L15: =IF(OR(J15="",K15=""),"",J15+K15) | M15: =IFERROR(INDEX(MCSI_Table!$B$2:$E$72,MATCH(L15,MCSI_Table!$A$2:$A$72,0),MATCH(B15,MCSI_Table!$B$1:$E$1,0)),"") | P15: =IF(OR(N15="",O15=""),"",N15+O15) | Q15: =IFERROR(INDEX(MCSI_Table!$B$2:$E$72,MATCH(P15,MCSI_Table!$A$2:$A$72,0),MATCH(B15,MCSI_Table!$B$1:$E$1,0)),"") | R15: =IF(OR(M15="",Q15=""),"",ROUND(M15+Q15,1)) | S15: =IF(OR(B15="",H15="",COUNT(D15:F15)<Settings!$B$5),"",ROUND((I15-H15)*Settings!$B$3,1)) -> 29.5 | T15: =IF(OR(R15="",S15=""),"",ROUND(R15+S15,1)) | U15: =IF(ISNUMBER(T15),1+COUNTIF($T$3:$T$51,">"&T15),"") | V15: =ScoresTable[[#This Row],[R1 Comp Scratch]]+ScoresTable[[#This Row],[R2 Comp Scratch]] -> 0 | W15: =ScoresTable[[#This Row],[R1 Comp Centres]]+ScoresTable[[#This Row],[R2 Comp Centres]] -> 0
A16: Beau McMaster | B16: FS | C16: BMRC | H16: =IF(COUNT(D16:G16)=0,"",ROUND(AVERAGE(D16:G16),1)) | I16: =IFERROR(VLOOKUP(B16,Settings!$A$8:$B$11,2,FALSE),"") -> 190 | L16: =IF(OR(J16="",K16=""),"",J16+K16) | M16: =IFERROR(INDEX(MCSI_Table!$B$2:$E$72,MATCH(L16,MCSI_Table!$A$2:$A$72,0),MATCH(B16,MCSI_Table!$B$1:$E$1,0)),"") | P16: =IF(OR(N16="",O16=""),"",N16+O16) | Q16: =IFERROR(INDEX(MCSI_Table!$B$2:$E$72,MATCH(P16,MCSI_Table!$A$2:$A$72,0),MATCH(B16,MCSI_Table!$B$1:$E$1,0)),"") | R16: =IF(OR(M16="",Q16=""),"",ROUND(M16+Q16,1)) | S16: =IF(OR(B16="",H16="",COUNT(D16:F16)<Settings!$B$5),"",ROUND((I16-H16)*Settings!$B$3,1)) | T16: =IF(OR(R16="",S16=""),"",ROUND(R16+S16,1)) | U16: =IF(ISNUMBER(T16),1+COUNTIF($T$3:$T$51,">"&T16),"") | V16: =ScoresTable[[#This Row],[R1 Comp Scratch]]+ScoresTable[[#This Row],[R2 Comp Scratch]] -> 0 | W16: =ScoresTable[[#This Row],[R1 Comp Centres]]+ScoresTable[[#This Row],[R2 Comp Centres]] -> 0
A17: Nichole Lister | B17: FO | C17: CRC | E17: 169.3 | G17: 174.4 | H17: =IF(COUNT(D17:G17)=0,"",ROUND(AVERAGE(D17:G17),1)) -> 171.9 | I17: =IFERROR(VLOOKUP(B17,Settings!$A$8:$B$11,2,FALSE),"") -> 190 | L17: =IF(OR(J17="",K17=""),"",J17+K17) | M17: =IFERROR(INDEX(MCSI_Table!$B$2:$E$72,MATCH(L17,MCSI_Table!$A$2:$A$72,0),MATCH(B17,MCSI_Table!$B$1:$E$1,0)),"") | P17: =IF(OR(N17="",O17=""),"",N17+O17) | Q17: =IFERROR(INDEX(MCSI_Table!$B$2:$E$72,MATCH(P17,MCSI_Table!$A$2:$A$72,0),MATCH(B17,MCSI_Table!$B$1:$E$1,0)),"") | R17: =IF(OR(M17="",Q17=""),"",ROUND(M17+Q17,1)) | S17: =IF(OR(B17="",H17="",COUNT(D17:F17)<Settings!$B$5),"",ROUND((I17-H17)*Settings!$B$3,1)) -> 12.7 | T17: =IF(OR(R17="",S17=""),"",ROUND(R17+S17,1)) | U17: =IF(ISNUMBER(T17),1+COUNTIF($T$3:$T$51,">"&T17),"") | V17: =ScoresTable[[#This Row],[R1 Comp Scratch]]+ScoresTable[[#This Row],[R2 Comp Scratch]] -> 0 | W17: =ScoresTable[[#This Row],[R1 Comp Centres]]+ScoresTable[[#This Row],[R2 Comp Centres]] -> 0
A18: James Hay | B18: FO | C18: CRC | E18: 186.8 | H18: =IF(COUNT(D18:G18)=0,"",ROUND(AVERAGE(D18:G18),1)) -> 186.8 | I18: =IFERROR(VLOOKUP(B18,Settings!$A$8:$B$11,2,FALSE),"") -> 190 | L18: =IF(OR(J18="",K18=""),"",J18+K18) | M18: =IFERROR(INDEX(MCSI_Table!$B$2:$E$72,MATCH(L18,MCSI_Table!$A$2:$A$72,0),MATCH(B18,MCSI_Table!$B$1:$E$1,0)),"") | P18: =IF(OR(N18="",O18=""),"",N18+O18) | Q18: =IFERROR(INDEX(MCSI_Table!$B$2:$E$72,MATCH(P18,MCSI_Table!$A$2:$A$72,0),MATCH(B18,MCSI_Table!$B$1:$E$1,0)),"") | R18: =IF(OR(M18="",Q18=""),"",ROUND(M18+Q18,1)) | S18: =IF(OR(B18="",H18="",COUNT(D18:F18)<Settings!$B$5),"",ROUND((I18-H18)*Settings!$B$3,1)) -> 2.2 | T18: =IF(OR(R18="",S18=""),"",ROUND(R18+S18,1)) | U18: =IF(ISNUMBER(T18),1+COUNTIF($T$3:$T$51,">"&T18),"") | V18: =ScoresTable[[#This Row],[R1 Comp Scratch]]+ScoresTable[[#This Row],[R2 Comp Scratch]] -> 0 | W18: =ScoresTable[[#This Row],[R1 Comp Centres]]+ScoresTable[[#This Row],[R2 Comp Centres]] -> 0
A19: Michael Hall | C19: CRC | E19: 170 | F19: 166.4 | H19: =IF(COUNT(D19:G19)=0,"",ROUND(AVERAGE(D19:G19),1)) -> 168.2 | I19: =IFERROR(VLOOKUP(B19,Settings!$A$8:$B$11,2,FALSE),"") | L19: =IF(OR(J19="",K19=""),"",J19+K19) | M19: =IFERROR(INDEX(MCSI_Table!$B$2:$E$72,MATCH(L19,MCSI_Table!$A$2:$A$72,0),MATCH(B19,MCSI_Table!$B$1:$E$1,0)),"") | P19: =IF(OR(N19="",O19=""),"",N19+O19) | Q19: =IFERROR(INDEX(MCSI_Table!$B$2:$E$72,MATCH(P19,MCSI_Table!$A$2:$A$72,0),MATCH(B19,MCSI_Table!$B$1:$E$1,0)),"") | R19: =IF(OR(M19="",Q19=""),"",ROUND(M19+Q19,1)) | S19: =IF(OR(B19="",H19="",COUNT(D19:F19)<Settings!$B$5),"",ROUND((I19-H19)*Settings!$B$3,1)) | T19: =IF(OR(R19="",S19=""),"",ROUND(R19+S19,1)) | U19: =IF(ISNUMBER(T19),1+COUNTIF($T$3:$T$51,">"&T19),"") | V19: =ScoresTable[[#This Row],[R1 Comp Scratch]]+ScoresTable[[#This Row],[R2 Comp Scratch]] -> 0 | W19: =ScoresTable[[#This Row],[R1 Comp Centres]]+ScoresTable[[#This Row],[R2 Comp Centres]] -> 0
A20: Adrian Rousler | C20: CRC | H20: =IF(COUNT(D20:G20)=0,"",ROUND(AVERAGE(D20:G20),1)) | I20: =IFERROR(VLOOKUP(B20,Settings!$A$8:$B$11,2,FALSE),"") | L20: =IF(OR(J20="",K20=""),"",J20+K20) | M20: =IFERROR(INDEX(MCSI_Table!$B$2:$E$72,MATCH(L20,MCSI_Table!$A$2:$A$72,0),MATCH(B20,MCSI_Table!$B$1:$E$1,0)),"") | P20: =IF(OR(N20="",O20=""),"",N20+O20) | Q20: =IFERROR(INDEX(MCSI_Table!$B$2:$E$72,MATCH(P20,MCSI_Table!$A$2:$A$72,0),MATCH(B20,MCSI_Table!$B$1:$E$1,0)),"") | R20: =IF(OR(M20="",Q20=""),"",ROUND(M20+Q20,1)) | S20: =IF(OR(B20="",H20="",COUNT(D20:F20)<Settings!$B$5),"",ROUND((I20-H20)*Settings!$B$3,1)) | T20: =IF(OR(R20="",S20=""),"",ROUND(R20+S20,1)) | U20: =IF(ISNUMBER(T20),1+COUNTIF($T$3:$T$51,">"&T20),"") | V20: =ScoresTable[[#This Row],[R1 Comp Scratch]]+ScoresTable[[#This Row],[R2 Comp Scratch]] -> 0 | W20: =ScoresTable[[#This Row],[R1 Comp Centres]]+ScoresTable[[#This Row],[R2 Comp Centres]] -> 0
A21: Liam Hall | C21: CRC | H21: =IF(COUNT(D21:G21)=0,"",ROUND(AVERAGE(D21:G21),1)) | I21: =IFERROR(VLOOKUP(B21,Settings!$A$8:$B$11,2,FALSE),"") | L21: =IF(OR(J21="",K21=""),"",J21+K21) | M21: =IFERROR(INDEX(MCSI_Table!$B$2:$E$72,MATCH(L21,MCSI_Table!$A$2:$A$72,0),MATCH(B21,MCSI_Table!$B$1:$E$1,0)),"") | P21: =IF(OR(N21="",O21=""),"",N21+O21) | Q21: =IFERROR(INDEX(MCSI_Table!$B$2:$E$72,MATCH(P21,MCSI_Table!$A$2:$A$72,0),MATCH(B21,MCSI_Table!$B$1:$E$1,0)),"") | R21: =IF(OR(M21="",Q21=""),"",ROUND(M21+Q21,1)) | S21: =IF(OR(B21="",H21="",COUNT(D21:F21)<Settings!$B$5),"",ROUND((I21-H21)*Settings!$B$3,1)) | T21: =IF(OR(R21="",S21=""),"",ROUND(R21+S21,1)) | U21: =IF(ISNUMBER(T21),1+COUNTIF($T$3:$T$51,">"&T21),"") | V21: =ScoresTable[[#This Row],[R1 Comp Scratch]]+ScoresTable[[#This Row],[R2 Comp Scratch]] -> 0 | W21: =ScoresTable[[#This Row],[R1 Comp Centres]]+ScoresTable[[#This Row],[R2 Comp Centres]] -> 0
A22: Oliver Bailey | C22: CRC | H22: =IF(COUNT(D22:G22)=0,"",ROUND(AVERAGE(D22:G22),1)) | I22: =IFERROR(VLOOKUP(B22,Settings!$A$8:$B$11,2,FALSE),"") | L22: =IF(OR(J22="",K22=""),"",J22+K22) | M22: =IFERROR(INDEX(MCSI_Table!$B$2:$E$72,MATCH(L22,MCSI_Table!$A$2:$A$72,0),MATCH(B22,MCSI_Table!$B$1:$E$1,0)),"") | P22: =IF(OR(N22="",O22=""),"",N22+O22) | Q22: =IFERROR(INDEX(MCSI_Table!$B$2:$E$72,MATCH(P22,MCSI_Table!$A$2:$A$72,0),MATCH(B22,MCSI_Table!$B$1:$E$1,0)),"") | R22: =IF(OR(M22="",Q22=""),"",ROUND(M22+Q22,1)) | S22: =IF(OR(B22="",H22="",COUNT(D22:F22)<Settings!$B$5),"",ROUND((I22-H22)*Settings!$B$3,1)) | T22: =IF(OR(R22="",S22=""),"",ROUND(R22+S22,1)) | U22: =IF(ISNUMBER(T22),1+COUNTIF($T$3:$T$51,">"&T22),"") | V22: =ScoresTable[[#This Row],[R1 Comp Scratch]]+ScoresTable[[#This Row],[R2 Comp Scratch]] -> 0 | W22: =ScoresTable[[#This Row],[R1 Comp Centres]]+ScoresTable[[#This Row],[R2 Comp Centres]] -> 0
A23: Nick Patogiannis | B23: FO | C23: GRC | E23: 169 | F23: 148 | G23: 146.8 | H23: =IF(COUNT(D23:G23)=0,"",ROUND(AVERAGE(D23:G23),1)) -> 154.6 | I23: =IFERROR(VLOOKUP(B23,Settings!$A$8:$B$11,2,FALSE),"") -> 190 | L23: =IF(OR(J23="",K23=""),"",J23+K23) | M23: =IFERROR(INDEX(MCSI_Table!$B$2:$E$72,MATCH(L23,MCSI_Table!$A$2:$A$72,0),MATCH(B23,MCSI_Table!$B$1:$E$1,0)),"") | P23: =IF(OR(N23="",O23=""),"",N23+O23) | Q23: =IFERROR(INDEX(MCSI_Table!$B$2:$E$72,MATCH(P23,MCSI_Table!$A$2:$A$72,0),MATCH(B23,MCSI_Table!$B$1:$E$1,0)),"") | R23: =IF(OR(M23="",Q23=""),"",ROUND(M23+Q23,1)) | S23: =IF(OR(B23="",H23="",COUNT(D23:F23)<Settings!$B$5),"",ROUND((I23-H23)*Settings!$B$3,1)) -> 24.8 | T23: =IF(OR(R23="",S23=""),"",ROUND(R23+S23,1)) | U23: =IF(ISNUMBER(T23),1+COUNTIF($T$3:$T$51,">"&T23),"") | V23: =ScoresTable[[#This Row],[R1 Comp Scratch]]+ScoresTable[[#This Row],[R2 Comp Scratch]] -> 0 | W23: =ScoresTable[[#This Row],[R1 Comp Centres]]+ScoresTable[[#This Row],[R2 Comp Centres]] -> 0
A24: Daryl Chapple | B24: FO | C24: GRC | F24: 150.8 | H24: =IF(COUNT(D24:G24)=0,"",ROUND(AVERAGE(D24:G24),1)) -> 150.8 | I24: =IFERROR(VLOOKUP(B24,Settings!$A$8:$B$11,2,FALSE),"") -> 190 | L24: =IF(OR(J24="",K24=""),"",J24+K24) | M24: =IFERROR(INDEX(MCSI_Table!$B$2:$E$72,MATCH(L24,MCSI_Table!$A$2:$A$72,0),MATCH(B24,MCSI_Table!$B$1:$E$1,0)),"") | P24: =IF(OR(N24="",O24=""),"",N24+O24) | Q24: =IFERROR(INDEX(MCSI_Table!$B$2:$E$72,MATCH(P24,MCSI_Table!$A$2:$A$72,0),MATCH(B24,MCSI_Table!$B$1:$E$1,0)),"") | R24: =IF(OR(M24="",Q24=""),"",ROUND(M24+Q24,1)) | S24: =IF(OR(B24="",H24="",COUNT(D24:F24)<Settings!$B$5),"",ROUND((I24-H24)*Settings!$B$3,1)) -> 27.4 | T24: =IF(OR(R24="",S24=""),"",ROUND(R24+S24,1)) | U24: =IF(ISNUMBER(T24),1+COUNTIF($T$3:$T$51,">"&T24),"") | V24: =ScoresTable[[#This Row],[R1 Comp Scratch]]+ScoresTable[[#This Row],[R2 Comp Scratch]] -> 0 | W24: =ScoresTable[[#This Row],[R1 Comp Centres]]+ScoresTable[[#This Row],[R2 Comp Centres]] -> 0
A25: Jacko Bending | B25: FO | C25: GRC | H25: =IF(COUNT(D25:G25)=0,"",ROUND(AVERAGE(D25:G25),1)) | I25: =IFERROR(VLOOKUP(B25,Settings!$A$8:$B$11,2,FALSE),"") -> 190 | L25: =IF(OR(J25="",K25=""),"",J25+K25) | M25: =IFERROR(INDEX(MCSI_Table!$B$2:$E$72,MATCH(L25,MCSI_Table!$A$2:$A$72,0),MATCH(B25,MCSI_Table!$B$1:$E$1,0)),"") | P25: =IF(OR(N25="",O25=""),"",N25+O25) | Q25: =IFERROR(INDEX(MCSI_Table!$B$2:$E$72,MATCH(P25,MCSI_Table!$A$2:$A$72,0),MATCH(B25,MCSI_Table!$B$1:$E$1,0)),"") | R25: =IF(OR(M25="",Q25=""),"",ROUND(M25+Q25,1)) | S25: =IF(OR(B25="",H25="",COUNT(D25:F25)<Settings!$B$5),"",ROUND((I25-H25)*Settings!$B$3,1)) | T25: =IF(OR(R25="",S25=""),"",ROUND(R25+S25,1)) | U25: =IF(ISNUMBER(T25),1+COUNTIF($T$3:$T$51,">"&T25),"") | V25: =ScoresTable[[#This Row],[R1 Comp Scratch]]+ScoresTable[[#This Row],[R2 Comp Scratch]] -> 0 | W25: =ScoresTable[[#This Row],[R1 Comp Centres]]+ScoresTable[[#This Row],[R2 Comp Centres]] -> 0
A26: Ian Parks | B26: FO | C26: GRC | H26: =IF(COUNT(D26:G26)=0,"",ROUND(AVERAGE(D26:G26),1)) | I26: =IFERROR(VLOOKUP(B26,Settings!$A$8:$B$11,2,FALSE),"") -> 190 | L26: =IF(OR(J26="",K26=""),"",J26+K26) | M26: =IFERROR(INDEX(MCSI_Table!$B$2:$E$72,MATCH(L26,MCSI_Table!$A$2:$A$72,0),MATCH(B26,MCSI_Table!$B$1:$E$1,0)),"") | P26: =IF(OR(N26="",O26=""),"",N26+O26) | Q26: =IFERROR(INDEX(MCSI_Table!$B$2:$E$72,MATCH(P26,MCSI_Table!$A$2:$A$72,0),MATCH(B26,MCSI_Table!$B$1:$E$1,0)),"") | R26: =IF(OR(M26="",Q26=""),"",ROUND(M26+Q26,1)) | S26: =IF(OR(B26="",H26="",COUNT(D26:F26)<Settings!$B$5),"",ROUND((I26-H26)*Settings!$B$3,1)) | T26: =IF(OR(R26="",S26=""),"",ROUND(R26+S26,1)) | U26: =IF(ISNUMBER(T26),1+COUNTIF($T$3:$T$51,">"&T26),"") | V26: =ScoresTable[[#This Row],[R1 Comp Scratch]]+ScoresTable[[#This Row],[R2 Comp Scratch]] -> 0 | W26: =ScoresTable[[#This Row],[R1 Comp Centres]]+ScoresTable[[#This Row],[R2 Comp Centres]] -> 0
A27: Steven Porter | B27: FS | C27: GRC | E27: 151.4 | F27: 124.3 | H27: =IF(COUNT(D27:G27)=0,"",ROUND(AVERAGE(D27:G27),1)) -> 137.9 | I27: =IFERROR(VLOOKUP(B27,Settings!$A$8:$B$11,2,FALSE),"") -> 190 | L27: =IF(OR(J27="",K27=""),"",J27+K27) | M27: =IFERROR(INDEX(MCSI_Table!$B$2:$E$72,MATCH(L27,MCSI_Table!$A$2:$A$72,0),MATCH(B27,MCSI_Table!$B$1:$E$1,0)),"") | P27: =IF(OR(N27="",O27=""),"",N27+O27) | Q27: =IFERROR(INDEX(MCSI_Table!$B$2:$E$72,MATCH(P27,MCSI_Table!$A$2:$A$72,0),MATCH(B27,MCSI_Table!$B$1:$E$1,0)),"") | R27: =IF(OR(M27="",Q27=""),"",ROUND(M27+Q27,1)) | S27: =IF(OR(B27="",H27="",COUNT(D27:F27)<Settings!$B$5),"",ROUND((I27-H27)*Settings!$B$3,1)) -> 36.5 | T27: =IF(OR(R27="",S27=""),"",ROUND(R27+S27,1)) | U27: =IF(ISNUMBER(T27),1+COUNTIF($T$3:$T$51,">"&T27),"") | V27: =ScoresTable[[#This Row],[R1 Comp Scratch]]+ScoresTable[[#This Row],[R2 Comp Scratch]] -> 0 | W27: =ScoresTable[[#This Row],[R1 Comp Centres]]+ScoresTable[[#This Row],[R2 Comp Centres]] -> 0
A28: Adrian Viccars | B28: FO | C28: GRC | E28: 159.3 | H28: =IF(COUNT(D28:G28)=0,"",ROUND(AVERAGE(D28:G28),1)) -> 159.3 | I28: =IFERROR(VLOOKUP(B28,Settings!$A$8:$B$11,2,FALSE),"") -> 190 | L28: =IF(OR(J28="",K28=""),"",J28+K28) | M28: =IFERROR(INDEX(MCSI_Table!$B$2:$E$72,MATCH(L28,MCSI_Table!$A$2:$A$72,0),MATCH(B28,MCSI_Table!$B$1:$E$1,0)),"") | P28: =IF(OR(N28="",O28=""),"",N28+O28) | Q28: =IFERROR(INDEX(MCSI_Table!$B$2:$E$72,MATCH(P28,MCSI_Table!$A$2:$A$72,0),MATCH(B28,MCSI_Table!$B$1:$E$1,0)),"") | R28: =IF(OR(M28="",Q28=""),"",ROUND(M28+Q28,1)) | S28: =IF(OR(B28="",H28="",COUNT(D28:F28)<Settings!$B$5),"",ROUND((I28-H28)*Settings!$B$3,1)) -> 21.5 | T28: =IF(OR(R28="",S28=""),"",ROUND(R28+S28,1)) | U28: =IF(ISNUMBER(T28),1+COUNTIF($T$3:$T$51,">"&T28),"") | V28: =ScoresTable[[#This Row],[R1 Comp Scratch]]+ScoresTable[[#This Row],[R2 Comp Scratch]] -> 0 | W28: =ScoresTable[[#This Row],[R1 Comp Centres]]+ScoresTable[[#This Row],[R2 Comp Centres]] -> 0
A29: Chris Beretta | B29: FO | C29: GRC | E29: 172.7 | H29: =IF(COUNT(D29:G29)=0,"",ROUND(AVERAGE(D29:G29),1)) -> 172.7 | I29: =IFERROR(VLOOKUP(B29,Settings!$A$8:$B$11,2,FALSE),"") -> 190 | L29: =IF(OR(J29="",K29=""),"",J29+K29) | M29: =IFERROR(INDEX(MCSI_Table!$B$2:$E$72,MATCH(L29,MCSI_Table!$A$2:$A$72,0),MATCH(B29,MCSI_Table!$B$1:$E$1,0)),"") | P29: =IF(OR(N29="",O29=""),"",N29+O29) | Q29: =IFERROR(INDEX(MCSI_Table!$B$2:$E$72,MATCH(P29,MCSI_Table!$A$2:$A$72,0),MATCH(B29,MCSI_Table!$B$1:$E$1,0)),"") | R29: =IF(OR(M29="",Q29=""),"",ROUND(M29+Q29,1)) | S29: =IF(OR(B29="",H29="",COUNT(D29:F29)<Settings!$B$5),"",ROUND((I29-H29)*Settings!$B$3,1)) -> 12.1 | T29: =IF(OR(R29="",S29=""),"",ROUND(R29+S29,1)) | U29: =IF(ISNUMBER(T29),1+COUNTIF($T$3:$T$51,">"&T29),"") | V29: =ScoresTable[[#This Row],[R1 Comp Scratch]]+ScoresTable[[#This Row],[R2 Comp Scratch]] -> 0 | W29: =ScoresTable[[#This Row],[R1 Comp Centres]]+ScoresTable[[#This Row],[R2 Comp Centres]] -> 0
A30: Helen Cubbidge | B30: FO | C30: GRC | E30: 169.8 | H30: =IF(COUNT(D30:G30)=0,"",ROUND(AVERAGE(D30:G30),1)) -> 169.8 | I30: =IFERROR(VLOOKUP(B30,Settings!$A$8:$B$11,2,FALSE),"") -> 190 | L30: =IF(OR(J30="",K30=""),"",J30+K30) | M30: =IFERROR(INDEX(MCSI_Table!$B$2:$E$72,MATCH(L30,MCSI_Table!$A$2:$A$72,0),MATCH(B30,MCSI_Table!$B$1:$E$1,0)),"") | P30: =IF(OR(N30="",O30=""),"",N30+O30) | Q30: =IFERROR(INDEX(MCSI_Table!$B$2:$E$72,MATCH(P30,MCSI_Table!$A$2:$A$72,0),MATCH(B30,MCSI_Table!$B$1:$E$1,0)),"") | R30: =IF(OR(M30="",Q30=""),"",ROUND(M30+Q30,1)) | S30: =IF(OR(B30="",H30="",COUNT(D30:F30)<Settings!$B$5),"",ROUND((I30-H30)*Settings!$B$3,1)) -> 14.1 | T30: =IF(OR(R30="",S30=""),"",ROUND(R30+S30,1)) | U30: =IF(ISNUMBER(T30),1+COUNTIF($T$3:$T$51,">"&T30),"") | V30: =ScoresTable[[#This Row],[R1 Comp Scratch]]+ScoresTable[[#This Row],[R2 Comp Scratch]] -> 0 | W30: =ScoresTable[[#This Row],[R1 Comp Centres]]+ScoresTable[[#This Row],[R2 Comp Centres]] -> 0
A31: Robert Bant | B31: FO | C31: GRC | H31: =IF(COUNT(D31:G31)=0,"",ROUND(AVERAGE(D31:G31),1)) | I31: =IFERROR(VLOOKUP(B31,Settings!$A$8:$B$11,2,FALSE),"") -> 190 | L31: =IF(OR(J31="",K31=""),"",J31+K31) | M31: =IFERROR(INDEX(MCSI_Table!$B$2:$E$72,MATCH(L31,MCSI_Table!$A$2:$A$72,0),MATCH(B31,MCSI_Table!$B$1:$E$1,0)),"") | P31: =IF(OR(N31="",O31=""),"",N31+O31) | Q31: =IFERROR(INDEX(MCSI_Table!$B$2:$E$72,MATCH(P31,MCSI_Table!$A$2:$A$72,0),MATCH(B31,MCSI_Table!$B$1:$E$1,0)),"") | R31: =IF(OR(M31="",Q31=""),"",ROUND(M31+Q31,1)) | S31: =IF(OR(B31="",H31="",COUNT(D31:F31)<Settings!$B$5),"",ROUND((I31-H31)*Settings!$B$3,1)) | T31: =IF(OR(R31="",S31=""),"",ROUND(R31+S31,1)) | U31: =IF(ISNUMBER(T31),1+COUNTIF($T$3:$T$51,">"&T31),"") | V31: =ScoresTable[[#This Row],[R1 Comp Scratch]]+ScoresTable[[#This Row],[R2 Comp Scratch]] -> 0 | W31: =ScoresTable[[#This Row],[R1 Comp Centres]]+ScoresTable[[#This Row],[R2 Comp Centres]] -> 0
A32: Carol Hulett | B32: FS | C32: GRC | H32: =IF(COUNT(D32:G32)=0,"",ROUND(AVERAGE(D32:G32),1)) | I32: =IFERROR(VLOOKUP(B32,Settings!$A$8:$B$11,2,FALSE),"") -> 190 | L32: =IF(OR(J32="",K32=""),"",J32+K32) | M32: =IFERROR(INDEX(MCSI_Table!$B$2:$E$72,MATCH(L32,MCSI_Table!$A$2:$A$72,0),MATCH(B32,MCSI_Table!$B$1:$E$1,0)),"") | P32: =IF(OR(N32="",O32=""),"",N32+O32) | Q32: =IFERROR(INDEX(MCSI_Table!$B$2:$E$72,MATCH(P32,MCSI_Table!$A$2:$A$72,0),MATCH(B32,MCSI_Table!$B$1:$E$1,0)),"") | R32: =IF(OR(M32="",Q32=""),"",ROUND(M32+Q32,1)) | S32: =IF(OR(B32="",H32="",COUNT(D32:F32)<Settings!$B$5),"",ROUND((I32-H32)*Settings!$B$3,1)) | T32: =IF(OR(R32="",S32=""),"",ROUND(R32+S32,1)) | U32: =IF(ISNUMBER(T32),1+COUNTIF($T$3:$T$51,">"&T32),"") | V32: =ScoresTable[[#This Row],[R1 Comp Scratch]]+ScoresTable[[#This Row],[R2 Comp Scratch]] -> 0 | W32: =ScoresTable[[#This Row],[R1 Comp Centres]]+ScoresTable[[#This Row],[R2 Comp Centres]] -> 0
A33: Sudjono Muljoatmodjo | B33: FTR | C33: GRC | H33: =IF(COUNT(D33:G33)=0,"",ROUND(AVERAGE(D33:G33),1)) | I33: =IFERROR(VLOOKUP(B33,Settings!$A$8:$B$11,2,FALSE),"") -> 190 | L33: =IF(OR(J33="",K33=""),"",J33+K33) | M33: =IFERROR(INDEX(MCSI_Table!$B$2:$E$72,MATCH(L33,MCSI_Table!$A$2:$A$72,0),MATCH(B33,MCSI_Table!$B$1:$E$1,0)),"") | P33: =IF(OR(N33="",O33=""),"",N33+O33) | Q33: =IFERROR(INDEX(MCSI_Table!$B$2:$E$72,MATCH(P33,MCSI_Table!$A$2:$A$72,0),MATCH(B33,MCSI_Table!$B$1:$E$1,0)),"") | R33: =IF(OR(M33="",Q33=""),"",ROUND(M33+Q33,1)) | S33: =IF(OR(B33="",H33="",COUNT(D33:F33)<Settings!$B$5),"",ROUND((I33-H33)*Settings!$B$3,1)) | T33: =IF(OR(R33="",S33=""),"",ROUND(R33+S33,1)) | U33: =IF(ISNUMBER(T33),1+COUNTIF($T$3:$T$51,">"&T33),"") | V33: =ScoresTable[[#This Row],[R1 Comp Scratch]]+ScoresTable[[#This Row],[R2 Comp Scratch]] -> 0 | W33: =ScoresTable[[#This Row],[R1 Comp Centres]]+ScoresTable[[#This Row],[R2 Comp Centres]] -> 0
A34: David Dredge | C34: GRC | E34: 145.8 | H34: =IF(COUNT(D34:G34)=0,"",ROUND(AVERAGE(D34:G34),1)) -> 145.8 | I34: =IFERROR(VLOOKUP(B34,Settings!$A$8:$B$11,2,FALSE),"") | L34: =IF(OR(J34="",K34=""),"",J34+K34) | M34: =IFERROR(INDEX(MCSI_Table!$B$2:$E$72,MATCH(L34,MCSI_Table!$A$2:$A$72,0),MATCH(B34,MCSI_Table!$B$1:$E$1,0)),"") | P34: =IF(OR(N34="",O34=""),"",N34+O34) | Q34: =IFERROR(INDEX(MCSI_Table!$B$2:$E$72,MATCH(P34,MCSI_Table!$A$2:$A$72,0),MATCH(B34,MCSI_Table!$B$1:$E$1,0)),"") | R34: =IF(OR(M34="",Q34=""),"",ROUND(M34+Q34,1)) | S34: =IF(OR(B34="",H34="",COUNT(D34:F34)<Settings!$B$5),"",ROUND((I34-H34)*Settings!$B$3,1)) | T34: =IF(OR(R34="",S34=""),"",ROUND(R34+S34,1)) | U34: =IF(ISNUMBER(T34),1+COUNTIF($T$3:$T$51,">"&T34),"") | V34: =ScoresTable[[#This Row],[R1 Comp Scratch]]+ScoresTable[[#This Row],[R2 Comp Scratch]] -> 0 | W34: =ScoresTable[[#This Row],[R1 Comp Centres]]+ScoresTable[[#This Row],[R2 Comp Centres]] -> 0
A35: Jason Webb | C35: GRC | H35: =IF(COUNT(D35:G35)=0,"",ROUND(AVERAGE(D35:G35),1)) | I35: =IFERROR(VLOOKUP(B35,Settings!$A$8:$B$11,2,FALSE),"") | L35: =IF(OR(J35="",K35=""),"",J35+K35) | M35: =IFERROR(INDEX(MCSI_Table!$B$2:$E$72,MATCH(L35,MCSI_Table!$A$2:$A$72,0),MATCH(B35,MCSI_Table!$B$1:$E$1,0)),"") | P35: =IF(OR(N35="",O35=""),"",N35+O35) | Q35: =IFERROR(INDEX(MCSI_Table!$B$2:$E$72,MATCH(P35,MCSI_Table!$A$2:$A$72,0),MATCH(B35,MCSI_Table!$B$1:$E$1,0)),"") | R35: =IF(OR(M35="",Q35=""),"",ROUND(M35+Q35,1)) | S35: =IF(OR(B35="",H35="",COUNT(D35:F35)<Settings!$B$5),"",ROUND((I35-H35)*Settings!$B$3,1)) | T35: =IF(OR(R35="",S35=""),"",ROUND(R35+S35,1)) | U35: =IF(ISNUMBER(T35),1+COUNTIF($T$3:$T$51,">"&T35),"") | V35: =ScoresTable[[#This Row],[R1 Comp Scratch]]+ScoresTable[[#This Row],[R2 Comp Scratch]] -> 0 | W35: =ScoresTable[[#This Row],[R1 Comp Centres]]+ScoresTable[[#This Row],[R2 Comp Centres]] -> 0
A36: Ryan Allen | C36: GRC | H36: =IF(COUNT(D36:G36)=0,"",ROUND(AVERAGE(D36:G36),1)) | I36: =IFERROR(VLOOKUP(B36,Settings!$A$8:$B$11,2,FALSE),"") | L36: =IF(OR(J36="",K36=""),"",J36+K36) | M36: =IFERROR(INDEX(MCSI_Table!$B$2:$E$72,MATCH(L36,MCSI_Table!$A$2:$A$72,0),MATCH(B36,MCSI_Table!$B$1:$E$1,0)),"") | P36: =IF(OR(N36="",O36=""),"",N36+O36) | Q36: =IFERROR(INDEX(MCSI_Table!$B$2:$E$72,MATCH(P36,MCSI_Table!$A$2:$A$72,0),MATCH(B36,MCSI_Table!$B$1:$E$1,0)),"") | R36: =IF(OR(M36="",Q36=""),"",ROUND(M36+Q36,1)) | S36: =IF(OR(B36="",H36="",COUNT(D36:F36)<Settings!$B$5),"",ROUND((I36-H36)*Settings!$B$3,1)) | T36: =IF(OR(R36="",S36=""),"",ROUND(R36+S36,1)) | U36: =IF(ISNUMBER(T36),1+COUNTIF($T$3:$T$51,">"&T36),"") | V36: =ScoresTable[[#This Row],[R1 Comp Scratch]]+ScoresTable[[#This Row],[R2 Comp Scratch]] -> 0 | W36: =ScoresTable[[#This Row],[R1 Comp Centres]]+ScoresTable[[#This Row],[R2 Comp Centres]] -> 0
A37: Stephen Morovitch | C37: GRC | H37: =IF(COUNT(D37:G37)=0,"",ROUND(AVERAGE(D37:G37),1)) | I37: =IFERROR(VLOOKUP(B37,Settings!$A$8:$B$11,2,FALSE),"") | L37: =IF(OR(J37="",K37=""),"",J37+K37) | M37: =IFERROR(INDEX(MCSI_Table!$B$2:$E$72,MATCH(L37,MCSI_Table!$A$2:$A$72,0),MATCH(B37,MCSI_Table!$B$1:$E$1,0)),"") | P37: =IF(OR(N37="",O37=""),"",N37+O37) | Q37: =IFERROR(INDEX(MCSI_Table!$B$2:$E$72,MATCH(P37,MCSI_Table!$A$2:$A$72,0),MATCH(B37,MCSI_Table!$B$1:$E$1,0)),"") | R37: =IF(OR(M37="",Q37=""),"",ROUND(M37+Q37,1)) | S37: =IF(OR(B37="",H37="",COUNT(D37:F37)<Settings!$B$5),"",ROUND((I37-H37)*Settings!$B$3,1)) | T37: =IF(OR(R37="",S37=""),"",ROUND(R37+S37,1)) | U37: =IF(ISNUMBER(T37),1+COUNTIF($T$3:$T$51,">"&T37),"") | V37: =ScoresTable[[#This Row],[R1 Comp Scratch]]+ScoresTable[[#This Row],[R2 Comp Scratch]] -> 0 | W37: =ScoresTable[[#This Row],[R1 Comp Centres]]+ScoresTable[[#This Row],[R2 Comp Centres]] -> 0
A38: Amanda Jewell | C38: PCRC | H38: =IF(COUNT(D38:G38)=0,"",ROUND(AVERAGE(D38:G38),1)) | I38: =IFERROR(VLOOKUP(B38,Settings!$A$8:$B$11,2,FALSE),"") | L38: =IF(OR(J38="",K38=""),"",J38+K38) | M38: =IFERROR(INDEX(MCSI_Table!$B$2:$E$72,MATCH(L38,MCSI_Table!$A$2:$A$72,0),MATCH(B38,MCSI_Table!$B$1:$E$1,0)),"") | P38: =IF(OR(N38="",O38=""),"",N38+O38) | Q38: =IFERROR(INDEX(MCSI_Table!$B$2:$E$72,MATCH(P38,MCSI_Table!$A$2:$A$72,0),MATCH(B38,MCSI_Table!$B$1:$E$1,0)),"") | R38: =IF(OR(M38="",Q38=""),"",ROUND(M38+Q38,1)) | S38: =IF(OR(B38="",H38="",COUNT(D38:F38)<Settings!$B$5),"",ROUND((I38-H38)*Settings!$B$3,1)) | T38: =IF(OR(R38="",S38=""),"",ROUND(R38+S38,1)) | U38: =IF(ISNUMBER(T38),1+COUNTIF($T$3:$T$51,">"&T38),"") | V38: =ScoresTable[[#This Row],[R1 Comp Scratch]]+ScoresTable[[#This Row],[R2 Comp Scratch]] -> 0 | W38: =ScoresTable[[#This Row],[R1 Comp Centres]]+ScoresTable[[#This Row],[R2 Comp Centres]] -> 0
A39: Mark Jewell | C39: PCRC | H39: =IF(COUNT(D39:G39)=0,"",ROUND(AVERAGE(D39:G39),1)) | I39: =IFERROR(VLOOKUP(B39,Settings!$A$8:$B$11,2,FALSE),"") | L39: =IF(OR(J39="",K39=""),"",J39+K39) | M39: =IFERROR(INDEX(MCSI_Table!$B$2:$E$72,MATCH(L39,MCSI_Table!$A$2:$A$72,0),MATCH(B39,MCSI_Table!$B$1:$E$1,0)),"") | P39: =IF(OR(N39="",O39=""),"",N39+O39) | Q39: =IFERROR(INDEX(MCSI_Table!$B$2:$E$72,MATCH(P39,MCSI_Table!$A$2:$A$72,0),MATCH(B39,MCSI_Table!$B$1:$E$1,0)),"") | R39: =IF(OR(M39="",Q39=""),"",ROUND(M39+Q39,1)) | S39: =IF(OR(B39="",H39="",COUNT(D39:F39)<Settings!$B$5),"",ROUND((I39-H39)*Settings!$B$3,1)) | T39: =IF(OR(R39="",S39=""),"",ROUND(R39+S39,1)) | U39: =IF(ISNUMBER(T39),1+COUNTIF($T$3:$T$51,">"&T39),"") | V39: =ScoresTable[[#This Row],[R1 Comp Scratch]]+ScoresTable[[#This Row],[R2 Comp Scratch]] -> 0 | W39: =ScoresTable[[#This Row],[R1 Comp Centres]]+ScoresTable[[#This Row],[R2 Comp Centres]] -> 0
A40: Michael Hall | B40: FTR | C40: SBRC | E40: 169.5 | H40: =IF(COUNT(D40:G40)=0,"",ROUND(AVERAGE(D40:G40),1)) -> 169.5 | I40: =IFERROR(VLOOKUP(B40,Settings!$A$8:$B$11,2,FALSE),"") -> 190 | L40: =IF(OR(J40="",K40=""),"",J40+K40) | M40: =IFERROR(INDEX(MCSI_Table!$B$2:$E$72,MATCH(L40,MCSI_Table!$A$2:$A$72,0),MATCH(B40,MCSI_Table!$B$1:$E$1,0)),"") | P40: =IF(OR(N40="",O40=""),"",N40+O40) | Q40: =IFERROR(INDEX(MCSI_Table!$B$2:$E$72,MATCH(P40,MCSI_Table!$A$2:$A$72,0),MATCH(B40,MCSI_Table!$B$1:$E$1,0)),"") | R40: =IF(OR(M40="",Q40=""),"",ROUND(M40+Q40,1)) | S40: =IF(OR(B40="",H40="",COUNT(D40:F40)<Settings!$B$5),"",ROUND((I40-H40)*Settings!$B$3,1)) -> 14.4 | T40: =IF(OR(R40="",S40=""),"",ROUND(R40+S40,1)) | U40: =IF(ISNUMBER(T40),1+COUNTIF($T$3:$T$51,">"&T40),"") | V40: =ScoresTable[[#This Row],[R1 Comp Scratch]]+ScoresTable[[#This Row],[R2 Comp Scratch]] -> 0 | W40: =ScoresTable[[#This Row],[R1 Comp Centres]]+ScoresTable[[#This Row],[R2 Comp Centres]] -> 0
...

Sheet MCSI_Table
A1: Lookup Score | B1: TR | C1: FS | D1: FO | E1: FTR
A2: 0 | B2: 0 | C2: 0 | D2: 0 | E2: 0
A3: 1 | B3: 1.7 | C3: 1.4 | D3: 1.3 | E3: 1.3
A4: 2 | B4: 3.4 | C4: 2.9 | D4: 2.6 | E4: 2.7
A5: 3 | B5: 5.1 | C5: 4.3 | D5: 3.8 | E5: 4
A6: 4 | B6: 6.8 | C6: 5.7 | D6: 5.1 | E6: 5.4
A7: 5 | B7: 8.5 | C7: 7.1 | D7: 6.4 | E7: 6.7
A8: 6 | B8: 10.2 | C8: 8.6 | D8: 7.7 | E8: 8.1
A9: 7 | B9: 11.9 | C9: 10 | D9: 8.9 | E9: 9.4
A10: 8 | B10: 13.6 | C10: 11.4 | D10: 10.2 | E10: 10.8
A11: 9 | B11: 15.3 | C11: 12.9 | D11: 11.5 | E11: 12.1
A12: 10 | B12: 17 | C12: 14.3 | D12: 12.8 | E12: 13.5
A13: 11 | B13: 18.7 | C13: 15.7 | D13: 14 | E13: 14.8
... A62: 60 | B62: 99.5 | C62: 85.7 | D62: 80.5 | E62: 83.2
A63: 61 | C63: 87.1 | D63: 82.2 | E63: 84.8
A64: 62 | C64: 88.6 | D64: 83.8 | E64: 86.3
A65: 63 | C65: 90 | D65: 85.5 | E65: 87.9
A66: 64 | C66: 91.4 | D66: 87.2 | E66: 89.5
A67: 65 | C67: 92.9 | D67: 88.9 | E67: 91
A68: 66 | C68: 94.3 | D68: 90.6 | E68: 92.6
A69: 67 | C69: 95.7 | D69: 92.4 | E69: 94.2
A70: 68 | C70: 97.1 | D70: 94.4 | E70: 95.9
A71: 69 | C71: 98.6 | D71: 96.5 | E71: 97.7
A72: 70 | C72: 100 | D72: 99.6 | E72: 99.8

Sheet Settings
A1: MCSI-14 Handicap Calculator Settings
A2: Setting | B2: Value | C2: Notes
A3: Handicap Factor | B3: 0.7 | C3: 70% of the gap between 190 benchmark and Average MCSI
A4: Handicap Cap | B4: No hard cap | C4: Cap removed - handicap is not limited to 10 points
A5: Minimum Prior Scores | B5: 1 | C5: Minimum previous MCSI scores required for handicap
A7: Class | B7: Target MCSI Benchmark | C7: R1/R2 Max Score | D7: R1/R2 Max Centres
A8: TR | B8: 190 | C8: 50 | D8: 10
A9: FO | B9: 190 | C9: 60 | D9: 10
A10: FS | B10: 190 | C10: 60 | D10: 10
A11: FTR | B11: 190 | C11: 60 | D11: 10

Sheet Instructions
A1: MCSI-14 Handicap Calculator Instructions
A2: Enter prior competition MCSI totals in columns D:K. These are not scratch scores.
A3: Average MCSI Score is calculated from available prior MCSI totals in D:K.
A4: Minimum prior scores is set to 1 in Settings so new shooters can still receive a handicap.
A5: Target MCSI Benchmark is set to 190 for TR/FO/FS/FTR in Settings.
A6: Handicap formula: (Target MCSI Benchmark - Average MCSI Score) × Handicap Factor.
A7: Handicap Factor is currently 0.70.
A8: No hard 10-point cap is applied.
A9: Handicap Adjusted Score = Total MCSI + Handicap.
A10: Rank is calculated from Handicap Adjusted Score, highest score ranked 1.
A11: R1/R2 Lookup columns add scratch and centres, then lookup the MCSI value from the MCSI_Table sheet.
A12: Update Settings if the benchmark or factor needs changing later.

Sheet Calcs
A1: Calcs Page
A2: Name | B2: Class | C2: Club | D2: CRC 2024 | E2: PCRC 2024 | F2: GRC 2024 | G2: WRC 2024 | H2: BMRC 2024 | I2: PCRC 2025 | J2: GRC 2025 | K2: BMRC 2025 | L2: Average MCSI Score | M2: Target MCSI Benchmark | N2: R1 Comp Scratch | O2: R1 Comp Centres | P2: R1 Lookup | Q2: R1 MCSI | R2: R2 Comp Scratch | S2: R2 Comp Centres | T2: R2 Lookup | U2: R2 MCSI | V2: Total MCSI | W2: Handicap | X2: Handicap Adjusted Score | Y2: Rank
A3: Beau McMaster | C3: BMRC | L3: =IF(COUNT(D3:K3)=0,"",ROUND(AVERAGE(D3:K3),1)) | M3: =IFERROR(VLOOKUP(B3,Settings!$A$8:$B$11,2,FALSE),"") | P3: =IF(OR(N3="",O3=""),"",N3+O3) | Q3: =IFERROR(INDEX(MCSI_Table!$B$2:$E$72,MATCH(P3,MCSI_Table!$A$2:$A$72,0),MATCH(B3,MCSI_Table!$B$1:$E$1,0)),"") | T3: =IF(OR(R3="",S3=""),"",R3+S3) | U3: =IFERROR(INDEX(MCSI_Table!$B$2:$E$72,MATCH(T3,MCSI_Table!$A$2:$A$72,0),MATCH(B3,MCSI_Table!$B$1:$E$1,0)),"") | V3: =IF(OR(Q3="",U3=""),"",ROUND(Q3+U3,1)) | W3: =IF(OR(B3="",L3="",COUNT(D3:K3)<Settings!$B$5),"",ROUND((M3-L3)*Settings!$B$3,1)) | X3: =IF(OR(V3="",W3=""),"",ROUND(V3+W3,1)) | Y3: =IF(ISNUMBER(X3),1+COUNTIF($X$3:$X$51,">"&X3),"")
A4: Bela Ori | B4: FS | C4: BMRC | L4: =IF(COUNT(D4:K4)=0,"",ROUND(AVERAGE(D4:K4),1)) | M4: =IFERROR(VLOOKUP(B4,Settings!$A$8:$B$11,2,FALSE),"") -> 190 | N4: 54 | O4: 1 | P4: =IF(OR(N4="",O4=""),"",N4+O4) -> 55 | Q4: =IFERROR(INDEX(MCSI_Table!$B$2:$E$72,MATCH(P4,MCSI_Table!$A$2:$A$72,0),MATCH(B4,MCSI_Table!$B$1:$E$1,0)),"") -> 78.6 | R4: 56 | S4: 2 | T4: =IF(OR(R4="",S4=""),"",R4+S4) -> 58 | U4: =IFERROR(INDEX(MCSI_Table!$B$2:$E$72,MATCH(T4,MCSI_Table!$A$2:$A$72,0),MATCH(B4,MCSI_Table!$B$1:$E$1,0)),"") -> 82.9 | V4: =IF(OR(Q4="",U4=""),"",ROUND(Q4+U4,1)) -> 161.5 | W4: =IF(OR(B4="",L4="",COUNT(D4:K4)<Settings!$B$5),"",ROUND((M4-L4)*Settings!$B$3,1)) | X4: =IF(OR(V4="",W4=""),"",ROUND(V4+W4,1)) | Y4: =IF(ISNUMBER(X4),1+COUNTIF($X$3:$X$51,">"&X4),"")
A5: Maya Ori | B5: FS | C5: BMRC | L5: =IF(COUNT(D5:K5)=0,"",ROUND(AVERAGE(D5:K5),1)) | M5: =IFERROR(VLOOKUP(B5,Settings!$A$8:$B$11,2,FALSE),"") -> 190 | N5: 50 | O5: 1 | P5: =IF(OR(N5="",O5=""),"",N5+O5) -> 51 | Q5: =IFERROR(INDEX(MCSI_Table!$B$2:$E$72,MATCH(P5,MCSI_Table!$A$2:$A$72,0),MATCH(B5,MCSI_Table!$B$1:$E$1,0)),"") -> 72.9 | R5: 59 | S5: 7 | T5: =IF(OR(R5="",S5=""),"",R5+S5) -> 66 | U5: =IFERROR(INDEX(MCSI_Table!$B$2:$E$72,MATCH(T5,MCSI_Table!$A$2:$A$72,0),MATCH(B5,MCSI_Table!$B$1:$E$1,0)),"") -> 94.3 | V5: =IF(OR(Q5="",U5=""),"",ROUND(Q5+U5,1)) -> 167.2 | W5: =IF(OR(B5="",L5="",COUNT(D5:K5)<Settings!$B$5),"",ROUND((M5-L5)*Settings!$B$3,1)) | X5: =IF(OR(V5="",W5=""),"",ROUND(V5+W5,1)) | Y5: =IF(ISNUMBER(X5),1+COUNTIF($X$3:$X$51,">"&X5),"")
A6: Richard Glen | B6: FS | C6: BMRC | L6: =IF(COUNT(D6:K6)=0,"",ROUND(AVERAGE(D6:K6),1)) | M6: =IFERROR(VLOOKUP(B6,Settings!$A$8:$B$11,2,FALSE),"") -> 190 | N6: 51 | O6: 0 | P6: =IF(OR(N6="",O6=""),"",N6+O6) -> 51 | Q6: =IFERROR(INDEX(MCSI_Table!$B$2:$E$72,MATCH(P6,MCSI_Table!$A$2:$A$72,0),MATCH(B6,MCSI_Table!$B$1:$E$1,0)),"") -> 72.9 | R6: 58 | S6: 2 | T6: =IF(OR(R6="",S6=""),"",R6+S6) -> 60 | U6: =IFERROR(INDEX(MCSI_Table!$B$2:$E$72,MATCH(T6,MCSI_Table!$A$2:$A$72,0),MATCH(B6,MCSI_Table!$B$1:$E$1,0)),"") -> 85.7 | V6: =IF(OR(Q6="",U6=""),"",ROUND(Q6+U6,1)) -> 158.6 | W6: =IF(OR(B6="",L6="",COUNT(D6:K6)<Settings!$B$5),"",ROUND((M6-L6)*Settings!$B$3,1)) | X6: =IF(OR(V6="",W6=""),"",ROUND(V6+W6,1)) | Y6: =IF(ISNUMBER(X6),1+COUNTIF($X$3:$X$51,">"&X6),"")
A7: Shane Malcolm | B7: FS | C7: BMRC | L7: =IF(COUNT(D7:K7)=0,"",ROUND(AVERAGE(D7:K7),1)) | M7: =IFERROR(VLOOKUP(B7,Settings!$A$8:$B$11,2,FALSE),"") -> 190 | N7: 59 | O7: 2 | P7: =IF(OR(N7="",O7=""),"",N7+O7) -> 61 | Q7: =IFERROR(INDEX(MCSI_Table!$B$2:$E$72,MATCH(P7,MCSI_Table!$A$2:$A$72,0),MATCH(B7,MCSI_Table!$B$1:$E$1,0)),"") -> 87.1 | R7: 60 | S7: 5 | T7: =IF(OR(R7="",S7=""),"",R7+S7) -> 65 | U7: =IFERROR(INDEX(MCSI_Table!$B$2:$E$72,MATCH(T7,MCSI_Table!$A$2:$A$72,0),MATCH(B7,MCSI_Table!$B$1:$E$1,0)),"") -> 92.9 | V7: =IF(OR(Q7="",U7=""),"",ROUND(Q7+U7,1)) -> 180 | W7: =IF(OR(B7="",L7="",COUNT(D7:K7)<Settings!$B$5),"",ROUND((M7-L7)*Settings!$B$3,1)) | X7: =IF(OR(V7="",W7=""),"",ROUND(V7+W7,1)) | Y7: =IF(ISNUMBER(X7),1+COUNTIF($X$3:$X$51,">"&X7),"")
A8: Adrian Rousler | C8: CRC | L8: =IF(COUNT(D8:K8)=0,"",ROUND(AVERAGE(D8:K8),1)) | M8: =IFERROR(VLOOKUP(B8,Settings!$A$8:$B$11,2,FALSE),"") | N8: 50 | O8: 1 | P8: =IF(OR(N8="",O8=""),"",N8+O8) -> 51 | Q8: =IFERROR(INDEX(MCSI_Table!$B$2:$E$72,MATCH(P8,MCSI_Table!$A$2:$A$72,0),MATCH(B8,MCSI_Table!$B$1:$E$1,0)),"") | R8: 51 | S8: 2 | T8: =IF(OR(R8="",S8=""),"",R8+S8) -> 53 | U8: =IFERROR(INDEX(MCSI_Table!$B$2:$E$72,MATCH(T8,MCSI_Table!$A$2:$A$72,0),MATCH(B8,MCSI_Table!$B$1:$E$1,0)),"") | V8: =IF(OR(Q8="",U8=""),"",ROUND(Q8+U8,1)) | W8: =IF(OR(B8="",L8="",COUNT(D8:K8)<Settings!$B$5),"",ROUND((M8-L8)*Settings!$B$3,1)) | X8: =IF(OR(V8="",W8=""),"",ROUND(V8+W8,1)) | Y8: =IF(ISNUMBER(X8),1+COUNTIF($X$3:$X$51,">"&X8),"")
A9: Brendan Wilson | B9: FS | C9: CRC | L9: =IF(COUNT(D9:K9)=0,"",ROUND(AVERAGE(D9:K9),1)) | M9: =IFERROR(VLOOKUP(B9,Settings!$A$8:$B$11,2,FALSE),"") -> 190 | N9: 58 | O9: 3 | P9: =IF(OR(N9="",O9=""),"",N9+O9) -> 61 | Q9: =IFERROR(INDEX(MCSI_Table!$B$2:$E$72,MATCH(P9,MCSI_Table!$A$2:$A$72,0),MATCH(B9,MCSI_Table!$B$1:$E$1,0)),"") -> 87.1 | R9: 60 | S9: 5 | T9: =IF(OR(R9="",S9=""),"",R9+S9) -> 65 | U9: =IFERROR(INDEX(MCSI_Table!$B$2:$E$72,MATCH(T9,MCSI_Table!$A$2:$A$72,0),MATCH(B9,MCSI_Table!$B$1:$E$1,0)),"") -> 92.9 | V9: =IF(OR(Q9="",U9=""),"",ROUND(Q9+U9,1)) -> 180 | W9: =IF(OR(B9="",L9="",COUNT(D9:K9)<Settings!$B$5),"",ROUND((M9-L9)*Settings!$B$3,1)) | X9: =IF(OR(V9="",W9=""),"",ROUND(V9+W9,1)) | Y9: =IF(ISNUMBER(X9),1+COUNTIF($X$3:$X$51,">"&X9),"")
A10: Garry Rose | B10: FO | C10: CRC | L10: =IF(COUNT(D10:K10)=0,"",ROUND(AVERAGE(D10:K10),1)) | M10: =IFERROR(VLOOKUP(B10,Settings!$A$8:$B$11,2,FALSE),"") -> 190 | N10: 60 | O10: 6 | P10: =IF(OR(N10="",O10=""),"",N10+O10) -> 66 | Q10: =IFERROR(INDEX(MCSI_Table!$B$2:$E$72,MATCH(P10,MCSI_Table!$A$2:$A$72,0),MATCH(B10,MCSI_Table!$B$1:$E$1,0)),"") -> 90.6 | R10: 60 | S10: 7 | T10: =IF(OR(R10="",S10=""),"",R10+S10) -> 67 | U10: =IFERROR(INDEX(MCSI_Table!$B$2:$E$72,MATCH(T10,MCSI_Table!$A$2:$A$72,0),MATCH(B10,MCSI_Table!$B$1:$E$1,0)),"") -> 92.4 | V10: =IF(OR(Q10="",U10=""),"",ROUND(Q10+U10,1)) -> 183 | W10: =IF(OR(B10="",L10="",COUNT(D10:K10)<Settings!$B$5),"",ROUND((M10-L10)*Settings!$B$3,1)) | X10: =IF(OR(V10="",W10=""),"",ROUND(V10+W10,1)) | Y10: =IF(ISNUMBER(X10),1+COUNTIF($X$3:$X$51,">"&X10),"")
A11: James Hay | B11: FO | C11: CRC | L11: =IF(COUNT(D11:K11)=0,"",ROUND(AVERAGE(D11:K11),1)) | M11: =IFERROR(VLOOKUP(B11,Settings!$A$8:$B$11,2,FALSE),"") -> 190 | N11: 60 | O11: 10 | P11: =IF(OR(N11="",O11=""),"",N11+O11) -> 70 | Q11: =IFERROR(INDEX(MCSI_Table!$B$2:$E$72,MATCH(P11,MCSI_Table!$A$2:$A$72,0),MATCH(B11,MCSI_Table!$B$1:$E$1,0)),"") -> 99.6 | R11: 60 | S11: 4 | T11: =IF(OR(R11="",S11=""),"",R11+S11) -> 64 | U11: =IFERROR(INDEX(MCSI_Table!$B$2:$E$72,MATCH(T11,MCSI_Table!$A$2:$A$72,0),MATCH(B11,MCSI_Table!$B$1:$E$1,0)),"") -> 87.2 | V11: =IF(OR(Q11="",U11=""),"",ROUND(Q11+U11,1)) -> 186.8 | W11: =IF(OR(B11="",L11="",COUNT(D11:K11)<Settings!$B$5),"",ROUND((M11-L11)*Settings!$B$3,1)) | X11: =IF(OR(V11="",W11=""),"",ROUND(V11+W11,1)) | Y11: =IF(ISNUMBER(X11),1+COUNTIF($X$3:$X$51,">"&X11),"")
A12: John Halifax | B12: FO | C12: CRC | L12: =IF(COUNT(D12:K12)=0,"",ROUND(AVERAGE(D12:K12),1)) | M12: =IFERROR(VLOOKUP(B12,Settings!$A$8:$B$11,2,FALSE),"") -> 190 | P12: =IF(OR(N12="",O12=""),"",N12+O12) | Q12: =IFERROR(INDEX(MCSI_Table!$B$2:$E$72,MATCH(P12,MCSI_Table!$A$2:$A$72,0),MATCH(B12,MCSI_Table!$B$1:$E$1,0)),"") | T12: =IF(OR(R12="",S12=""),"",R12+S12) | U12: =IFERROR(INDEX(MCSI_Table!$B$2:$E$72,MATCH(T12,MCSI_Table!$A$2:$A$72,0),MATCH(B12,MCSI_Table!$B$1:$E$1,0)),"") | V12: =IF(OR(Q12="",U12=""),"",ROUND(Q12+U12,1)) | W12: =IF(OR(B12="",L12="",COUNT(D12:K12)<Settings!$B$5),"",ROUND((M12-L12)*Settings!$B$3,1)) | X12: =IF(OR(V12="",W12=""),"",ROUND(V12+W12,1)) | Y12: =IF(ISNUMBER(X12),1+COUNTIF($X$3:$X$51,">"&X12),"")
A13: Liam Hall | C13: CRC | L13: =IF(COUNT(D13:K13)=0,"",ROUND(AVERAGE(D13:K13),1)) | M13: =IFERROR(VLOOKUP(B13,Settings!$A$8:$B$11,2,FALSE),"") | P13: =IF(OR(N13="",O13=""),"",N13+O13) | Q13: =IFERROR(INDEX(MCSI_Table!$B$2:$E$72,MATCH(P13,MCSI_Table!$A$2:$A$72,0),MATCH(B13,MCSI_Table!$B$1:$E$1,0)),"") | T13: =IF(OR(R13="",S13=""),"",R13+S13) | U13: =IFERROR(INDEX(MCSI_Table!$B$2:$E$72,MATCH(T13,MCSI_Table!$A$2:$A$72,0),MATCH(B13,MCSI_Table!$B$1:$E$1,0)),"") | V13: =IF(OR(Q13="",U13=""),"",ROUND(Q13+U13,1)) | W13: =IF(OR(B13="",L13="",COUNT(D13:K13)<Settings!$B$5),"",ROUND((M13-L13)*Settings!$B$3,1)) | X13: =IF(OR(V13="",W13=""),"",ROUND(V13+W13,1)) | Y13: =IF(ISNUMBER(X13),1+COUNTIF($X$3:$X$51,">"&X13),"")
A14: Michael Hall | C14: CRC | L14: =IF(COUNT(D14:K14)=0,"",ROUND(AVERAGE(D14:K14),1)) | M14: =IFERROR(VLOOKUP(B14,Settings!$A$8:$B$11,2,FALSE),"") | P14: =IF(OR(N14="",O14=""),"",N14+O14) | Q14: =IFERROR(INDEX(MCSI_Table!$B$2:$E$72,MATCH(P14,MCSI_Table!$A$2:$A$72,0),MATCH(B14,MCSI_Table!$B$1:$E$1,0)),"") | T14: =IF(OR(R14="",S14=""),"",R14+S14) | U14: =IFERROR(INDEX(MCSI_Table!$B$2:$E$72,MATCH(T14,MCSI_Table!$A$2:$A$72,0),MATCH(B14,MCSI_Table!$B$1:$E$1,0)),"") | V14: =IF(OR(Q14="",U14=""),"",ROUND(Q14+U14,1)) | W14: =IF(OR(B14="",L14="",COUNT(D14:K14)<Settings!$B$5),"",ROUND((M14-L14)*Settings!$B$3,1)) | X14: =IF(OR(V14="",W14=""),"",ROUND(V14+W14,1)) | Y14: =IF(ISNUMBER(X14),1+COUNTIF($X$3:$X$51,">"&X14),"")
A15: Mike Evans | B15: FS | C15: CRC | L15: =IF(COUNT(D15:K15)=0,"",ROUND(AVERAGE(D15:K15),1)) | M15: =IFERROR(VLOOKUP(B15,Settings!$A$8:$B$11,2,FALSE),"") -> 190 | N15: 59 | O15: 7 | P15: =IF(OR(N15="",O15=""),"",N15+O15) -> 66 | Q15: =IFERROR(INDEX(MCSI_Table!$B$2:$E$72,MATCH(P15,MCSI_Table!$A$2:$A$72,0),MATCH(B15,MCSI_Table!$B$1:$E$1,0)),"") -> 94.3 | R15: 59 | S15: 5 | T15: =IF(OR(R15="",S15=""),"",R15+S15) -> 64 | U15: =IFERROR(INDEX(MCSI_Table!$B$2:$E$72,MATCH(T15,MCSI_Table!$A$2:$A$72,0),MATCH(B15,MCSI_Table!$B$1:$E$1,0)),"") -> 91.4 | V15: =IF(OR(Q15="",U15=""),"",ROUND(Q15+U15,1)) -> 185.7 | W15: =IF(OR(B15="",L15="",COUNT(D15:K15)<Settings!$B$5),"",ROUND((M15-L15)*Settings!$B$3,1)) | X15: =IF(OR(V15="",W15=""),"",ROUND(V15+W15,1)) | Y15: =IF(ISNUMBER(X15),1+COUNTIF($X$3:$X$51,">"&X15),"")
A16: Nichole Lister | B16: FO | C16: CRC | L16: =IF(COUNT(D16:K16)=0,"",ROUND(AVERAGE(D16:K16),1)) | M16: =IFERROR(VLOOKUP(B16,Settings!$A$8:$B$11,2,FALSE),"") -> 190 | N16: 59 | O16: 4 | P16: =IF(OR(N16="",O16=""),"",N16+O16) -> 63 | Q16: =IFERROR(INDEX(MCSI_Table!$B$2:$E$72,MATCH(P16,MCSI_Table!$A$2:$A$72,0),MATCH(B16,MCSI_Table!$B$1:$E$1,0)),"") -> 85.5 | R16: 58 | S16: 4 | T16: =IF(OR(R16="",S16=""),"",R16+S16) -> 62 | U16: =IFERROR(INDEX(MCSI_Table!$B$2:$E$72,MATCH(T16,MCSI_Table!$A$2:$A$72,0),MATCH(B16,MCSI_Table!$B$1:$E$1,0)),"") -> 83.8 | V16: =IF(OR(Q16="",U16=""),"",ROUND(Q16+U16,1)) -> 169.3 | W16: =IF(OR(B16="",L16="",COUNT(D16:K16)<Settings!$B$5),"",ROUND((M16-L16)*Settings!$B$3,1)) | X16: =IF(OR(V16="",W16=""),"",ROUND(V16+W16,1)) | Y16: =IF(ISNUMBER(X16),1+COUNTIF($X$3:$X$51,">"&X16),"")
A17: Oliver Bailey | C17: CRC | L17: =IF(COUNT(D17:K17)=0,"",ROUND(AVERAGE(D17:K17),1)) | M17: =IFERROR(VLOOKUP(B17,Settings!$A$8:$B$11,2,FALSE),"") | P17: =IF(OR(N17="",O17=""),"",N17+O17) | Q17: =IFERROR(INDEX(MCSI_Table!$B$2:$E$72,MATCH(P17,MCSI_Table!$A$2:$A$72,0),MATCH(B17,MCSI_Table!$B$1:$E$1,0)),"") | T17: =IF(OR(R17="",S17=""),"",R17+S17) | U17: =IFERROR(INDEX(MCSI_Table!$B$2:$E$72,MATCH(T17,MCSI_Table!$A$2:$A$72,0),MATCH(B17,MCSI_Table!$B$1:$E$1,0)),"") | V17: =IF(OR(Q17="",U17=""),"",ROUND(Q17+U17,1)) | W17: =IF(OR(B17="",L17="",COUNT(D17:K17)<Settings!$B$5),"",ROUND((M17-L17)*Settings!$B$3,1)) | X17: =IF(OR(V17="",W17=""),"",ROUND(V17+W17,1)) | Y17: =IF(ISNUMBER(X17),1+COUNTIF($X$3:$X$51,">"&X17),"")
A18: Philip Sternhoght | C18: CRC | L18: =IF(COUNT(D18:K18)=0,"",ROUND(AVERAGE(D18:K18),1)) | M18: =IFERROR(VLOOKUP(B18,Settings!$A$8:$B$11,2,FALSE),"") | P18: =IF(OR(N18="",O18=""),"",N18+O18) | Q18: =IFERROR(INDEX(MCSI_Table!$B$2:$E$72,MATCH(P18,MCSI_Table!$A$2:$A$72,0),MATCH(B18,MCSI_Table!$B$1:$E$1,0)),"") | T18: =IF(OR(R18="",S18=""),"",R18+S18) | U18: =IFERROR(INDEX(MCSI_Table!$B$2:$E$72,MATCH(T18,MCSI_Table!$A$2:$A$72,0),MATCH(B18,MCSI_Table!$B$1:$E$1,0)),"") | V18: =IF(OR(Q18="",U18=""),"",ROUND(Q18+U18,1)) | W18: =IF(OR(B18="",L18="",COUNT(D18:K18)<Settings!$B$5),"",ROUND((M18-L18)*Settings!$B$3,1)) | X18: =IF(OR(V18="",W18=""),"",ROUND(V18+W18,1)) | Y18: =IF(ISNUMBER(X18),1+COUNTIF($X$3:$X$51,">"&X18),"")
A19: Adrian Viccars | B19: FO | C19: GRC | L19: =IF(COUNT(D19:K19)=0,"",ROUND(AVERAGE(D19:K19),1)) | M19: =IFERROR(VLOOKUP(B19,Settings!$A$8:$B$11,2,FALSE),"") -> 190 | N19: 58 | O19: 3 | P19: =IF(OR(N19="",O19=""),"",N19+O19) -> 61 | Q19: =IFERROR(INDEX(MCSI_Table!$B$2:$E$72,MATCH(P19,MCSI_Table!$A$2:$A$72,0),MATCH(B19,MCSI_Table!$B$1:$E$1,0)),"") -> 82.2 | R19: 57 | S19: 1 | T19: =IF(OR(R19="",S19=""),"",R19+S19) -> 58 | U19: =IFERROR(INDEX(MCSI_Table!$B$2:$E$72,MATCH(T19,MCSI_Table!$A$2:$A$72,0),MATCH(B19,MCSI_Table!$B$1:$E$1,0)),"") -> 77.1 | V19: =IF(OR(Q19="",U19=""),"",ROUND(Q19+U19,1)) -> 159.3 | W19: =IF(OR(B19="",L19="",COUNT(D19:K19)<Settings!$B$5),"",ROUND((M19-L19)*Settings!$B$3,1)) | X19: =IF(OR(V19="",W19=""),"",ROUND(V19+W19,1)) | Y19: =IF(ISNUMBER(X19),1+COUNTIF($X$3:$X$51,">"&X19),"")
A20: Andrew Cook | B20: FS | C20: GRC | L20: =IF(COUNT(D20:K20)=0,"",ROUND(AVERAGE(D20:K20),1)) | M20: =IFERROR(VLOOKUP(B20,Settings!$A$8:$B$11,2,FALSE),"") -> 190 | N20: 57 | O20: 3 | P20: =IF(OR(N20="",O20=""),"",N20+O20) -> 60 | Q20: =IFERROR(INDEX(MCSI_Table!$B$2:$E$72,MATCH(P20,MCSI_Table!$A$2:$A$72,0),MATCH(B20,MCSI_Table!$B$1:$E$1,0)),"") -> 85.7 | R20: 58 | S20: 3 | T20: =IF(OR(R20="",S20=""),"",R20+S20) -> 61 | U20: =IFERROR(INDEX(MCSI_Table!$B$2:$E$72,MATCH(T20,MCSI_Table!$A$2:$A$72,0),MATCH(B20,MCSI_Table!$B$1:$E$1,0)),"") -> 87.1 | V20: =IF(OR(Q20="",U20=""),"",ROUND(Q20+U20,1)) -> 172.8 | W20: =IF(OR(B20="",L20="",COUNT(D20:K20)<Settings!$B$5),"",ROUND((M20-L20)*Settings!$B$3,1)) | X20: =IF(OR(V20="",W20=""),"",ROUND(V20+W20,1)) | Y20: =IF(ISNUMBER(X20),1+COUNTIF($X$3:$X$51,">"&X20),"")
A21: Carol Hulett | B21: FS | C21: GRC | L21: =IF(COUNT(D21:K21)=0,"",ROUND(AVERAGE(D21:K21),1)) | M21: =IFERROR(VLOOKUP(B21,Settings!$A$8:$B$11,2,FALSE),"") -> 190 | P21: =IF(OR(N21="",O21=""),"",N21+O21) | Q21: =IFERROR(INDEX(MCSI_Table!$B$2:$E$72,MATCH(P21,MCSI_Table!$A$2:$A$72,0),MATCH(B21,MCSI_Table!$B$1:$E$1,0)),"") | T21: =IF(OR(R21="",S21=""),"",R21+S21) | U21: =IFERROR(INDEX(MCSI_Table!$B$2:$E$72,MATCH(T21,MCSI_Table!$A$2:$A$72,0),MATCH(B21,MCSI_Table!$B$1:$E$1,0)),"") | V21: =IF(OR(Q21="",U21=""),"",ROUND(Q21+U21,1)) | W21: =IF(OR(B21="",L21="",COUNT(D21:K21)<Settings!$B$5),"",ROUND((M21-L21)*Settings!$B$3,1)) | X21: =IF(OR(V21="",W21=""),"",ROUND(V21+W21,1)) | Y21: =IF(ISNUMBER(X21),1+COUNTIF($X$3:$X$51,">"&X21),"")
A22: Chris Beretta | B22: FO | C22: GRC | L22: =IF(COUNT(D22:K22)=0,"",ROUND(AVERAGE(D22:K22),1)) | M22: =IFERROR(VLOOKUP(B22,Settings!$A$8:$B$11,2,FALSE),"") -> 190 | N22: 58 | O22: 4 | P22: =IF(OR(N22="",O22=""),"",N22+O22) -> 62 | Q22: =IFERROR(INDEX(MCSI_Table!$B$2:$E$72,MATCH(P22,MCSI_Table!$A$2:$A$72,0),MATCH(B22,MCSI_Table!$B$1:$E$1,0)),"") -> 83.8 | R22: 60 | S22: 5 | T22: =IF(OR(R22="",S22=""),"",R22+S22) -> 65 | U22: =IFERROR(INDEX(MCSI_Table!$B$2:$E$72,MATCH(T22,MCSI_Table!$A$2:$A$72,0),MATCH(B22,MCSI_Table!$B$1:$E$1,0)),"") -> 88.9 | V22: =IF(OR(Q22="",U22=""),"",ROUND(Q22+U22,1)) -> 172.7 | W22: =IF(OR(B22="",L22="",COUNT(D22:K22)<Settings!$B$5),"",ROUND((M22-L22)*Settings!$B$3,1)) | X22: =IF(OR(V22="",W22=""),"",ROUND(V22+W22,1)) | Y22: =IF(ISNUMBER(X22),1+COUNTIF($X$3:$X$51,">"&X22),"")
A23: Daryl Chapple | B23: FO | C23: GRC | L23: =IF(COUNT(D23:K23)=0,"",ROUND(AVERAGE(D23:K23),1)) | M23: =IFERROR(VLOOKUP(B23,Settings!$A$8:$B$11,2,FALSE),"") -> 190 | N23: 59 | O23: 5 | P23: =IF(OR(N23="",O23=""),"",N23+O23) -> 64 | Q23: =IFERROR(INDEX(MCSI_Table!$B$2:$E$72,MATCH(P23,MCSI_Table!$A$2:$A$72,0),MATCH(B23,MCSI_Table!$B$1:$E$1,0)),"") -> 87.2 | R23: 59 | S23: 6 | T23: =IF(OR(R23="",S23=""),"",R23+S23) -> 65 | U23: =IFERROR(INDEX(MCSI_Table!$B$2:$E$72,MATCH(T23,MCSI_Table!$A$2:$A$72,0),MATCH(B23,MCSI_Table!$B$1:$E$1,0)),"") -> 88.9 | V23: =IF(OR(Q23="",U23=""),"",ROUND(Q23+U23,1)) -> 176.1 | W23: =IF(OR(B23="",L23="",COUNT(D23:K23)<Settings!$B$5),"",ROUND((M23-L23)*Settings!$B$3,1)) | X23: =IF(OR(V23="",W23=""),"",ROUND(V23+W23,1)) | Y23: =IF(ISNUMBER(X23),1+COUNTIF($X$3:$X$51,">"&X23),"")
A24: David Dredge | B24: FO | C24: GRC | L24: =IF(COUNT(D24:K24)=0,"",ROUND(AVERAGE(D24:K24),1)) | M24: =IFERROR(VLOOKUP(B24,Settings!$A$8:$B$11,2,FALSE),"") -> 190 | N24: 50 | O24: 2 | P24: =IF(OR(N24="",O24=""),"",N24+O24) -> 52 | Q24: =IFERROR(INDEX(MCSI_Table!$B$2:$E$72,MATCH(P24,MCSI_Table!$A$2:$A$72,0),MATCH(B24,MCSI_Table!$B$1:$E$1,0)),"") -> 67 | R24: 56 | S24: 3 | T24: =IF(OR(R24="",S24=""),"",R24+S24) -> 59 | U24: =IFERROR(INDEX(MCSI_Table!$B$2:$E$72,MATCH(T24,MCSI_Table!$A$2:$A$72,0),MATCH(B24,MCSI_Table!$B$1:$E$1,0)),"") -> 78.8 | V24: =IF(OR(Q24="",U24=""),"",ROUND(Q24+U24,1)) -> 145.8 | W24: =IF(OR(B24="",L24="",COUNT(D24:K24)<Settings!$B$5),"",ROUND((M24-L24)*Settings!$B$3,1)) | X24: =IF(OR(V24="",W24=""),"",ROUND(V24+W24,1)) | Y24: =IF(ISNUMBER(X24),1+COUNTIF($X$3:$X$51,">"&X24),"")
A25: David Shepard | B25: FS | C25: GRC | L25: =IF(COUNT(D25:K25)=0,"",ROUND(AVERAGE(D25:K25),1)) | M25: =IFERROR(VLOOKUP(B25,Settings!$A$8:$B$11,2,FALSE),"") -> 190 | N25: 52 | O25: 1 | P25: =IF(OR(N25="",O25=""),"",N25+O25) -> 53 | Q25: =IFERROR(INDEX(MCSI_Table!$B$2:$E$72,MATCH(P25,MCSI_Table!$A$2:$A$72,0),MATCH(B25,MCSI_Table!$B$1:$E$1,0)),"") -> 75.7 | R25: 60 | S25: 2 | T25: =IF(OR(R25="",S25=""),"",R25+S25) -> 62 | U25: =IFERROR(INDEX(MCSI_Table!$B$2:$E$72,MATCH(T25,MCSI_Table!$A$2:$A$72,0),MATCH(B25,MCSI_Table!$B$1:$E$1,0)),"") -> 88.6 | V25: =IF(OR(Q25="",U25=""),"",ROUND(Q25+U25,1)) -> 164.3 | W25: =IF(OR(B25="",L25="",COUNT(D25:K25)<Settings!$B$5),"",ROUND((M25-L25)*Settings!$B$3,1)) | X25: =IF(OR(V25="",W25=""),"",ROUND(V25+W25,1)) | Y25: =IF(ISNUMBER(X25),1+COUNTIF($X$3:$X$51,">"&X25),"")
A26: Helen Cubbidge | B26: FO | C26: GRC | L26: =IF(COUNT(D26:K26)=0,"",ROUND(AVERAGE(D26:K26),1)) | M26: =IFERROR(VLOOKUP(B26,Settings!$A$8:$B$11,2,FALSE),"") -> 190 | N26: 57 | O26: 0 | P26: =IF(OR(N26="",O26=""),"",N26+O26) -> 57 | Q26: =IFERROR(INDEX(MCSI_Table!$B$2:$E$72,MATCH(P26,MCSI_Table!$A$2:$A$72,0),MATCH(B26,MCSI_Table!$B$1:$E$1,0)),"") -> 75.4 | R26: 60 | S26: 8 | T26: =IF(OR(R26="",S26=""),"",R26+S26) -> 68 | U26: =IFERROR(INDEX(MCSI_Table!$B$2:$E$72,MATCH(T26,MCSI_Table!$A$2:$A$72,0),MATCH(B26,MCSI_Table!$B$1:$E$1,0)),"") -> 94.4 | V26: =IF(OR(Q26="",U26=""),"",ROUND(Q26+U26,1)) -> 169.8 | W26: =IF(OR(B26="",L26="",COUNT(D26:K26)<Settings!$B$5),"",ROUND((M26-L26)*Settings!$B$3,1)) | X26: =IF(OR(V26="",W26=""),"",ROUND(V26+W26,1)) | Y26: =IF(ISNUMBER(X26),1+COUNTIF($X$3:$X$51,">"&X26),"")
A27: Ian Parks | B27: FO | C27: GRC | L27: =IF(COUNT(D27:K27)=0,"",ROUND(AVERAGE(D27:K27),1)) | M27: =IFERROR(VLOOKUP(B27,Settings!$A$8:$B$11,2,FALSE),"") -> 190 | N27: 60 | O27: 6 | P27: =IF(OR(N27="",O27=""),"",N27+O27) -> 66 | Q27: =IFERROR(INDEX(MCSI_Table!$B$2:$E$72,MATCH(P27,MCSI_Table!$A$2:$A$72,0),MATCH(B27,MCSI_Table!$B$1:$E$1,0)),"") -> 90.6 | R27: 60 | S27: 5 | T27: =IF(OR(R27="",S27=""),"",R27+S27) -> 65 | U27: =IFERROR(INDEX(MCSI_Table!$B$2:$E$72,MATCH(T27,MCSI_Table!$A$2:$A$72,0),MATCH(B27,MCSI_Table!$B$1:$E$1,0)),"") -> 88.9 | V27: =IF(OR(Q27="",U27=""),"",ROUND(Q27+U27,1)) -> 179.5 | W27: =IF(OR(B27="",L27="",COUNT(D27:K27)<Settings!$B$5),"",ROUND((M27-L27)*Settings!$B$3,1)) | X27: =IF(OR(V27="",W27=""),"",ROUND(V27+W27,1)) | Y27: =IF(ISNUMBER(X27),1+COUNTIF($X$3:$X$51,">"&X27),"")
